Workbook
Name DashboardMonths: 'Dashboard Calc'!$I$2:$I$13

Sheet Capa
A1: RELATÓRIO CLARO TROCA — TRADE-IN
A2: Painel de acompanhamento Brasil | visão executiva, regional, parceiros e operação semanal
A4: 📍 NAVEGAÇÃO DO RELATÓRIO
A6: ABA | B6: FINALIDADE
A7: Dashboard | B7: Resumo executivo mensal, KPIs, gráficos e prioridades regionais.
A8: TOP 10 Parceiros | B8: Ranking nacional por Attachment consolidado entre regionais.
A9: REGIONAL | B9: Cobertura de PDVs e desempenho por regional.
A10: GRUPOS ZERADOS | B10: Grupos com e sem Claro Troca por regional.
A11: GRUPOS | B11: Histórico mensal consolidado por grupo rede.
A12: PDVS | B12: Histórico e elegibilidade por ponto de venda.
A13: BASE | B13: Dados importados semanalmente do BI.
A14: INSTRUÇÕES | B14: Rotina de atualização e validações do relatório.
A17: 🔄 ROTINA SEMANAL
A19: 1 | B19: Anexe a nova extração do BI e use o prompt de atualização semanal.
A20: 2 | B20: Confirme que BASE e PDVS fecham no mesmo total de Claro Troca.
A21: 3 | B21: Use o Dashboard para direcionar as provocações às regionais.

Sheet Dashboard
A1: PAINEL EXECUTIVO — CLARO TROCA | M1: MÊS | N1: CLARO TROCA
A2: Visão Brasil para acompanhamento semanal de performance, cobertura e oportunidades regionais. | M2: 46023 | N2: ='Dashboard Calc'!J2 -> 2001
A3: 📅 MÊS | B3: 46235 | D3: ="Atualizado com "&TEXT(COUNTIFS(BASE!$A:$A,$B$3),"#,##0")&" PDVs na base do mês selecionado" -> Atualizado com 997,0 PDVs na base do mês selecionado | M3: 46054 | N3: ='Dashboard Calc'!J3 -> 1657
M4: 46082 | N4: ='Dashboard Calc'!J4 -> 2965
A5: 🔁 CLARO TROCA | D5: 📈 ATTACHMENT | G5: 🎯 PDVs ELEGÍVEIS | J5: 🧩 GRUPOS A ATIVAR | M5: 46113 | N5: ='Dashboard Calc'!J5 -> 2364
A6: =SUMIFS(BASE!$G:$G,BASE!$A:$A,$B$3) -> 3844 | D6: =IFERROR(SUMIFS(BASE!$G:$G,BASE!$A:$A,$B$3)/SUMIFS(BASE!$F:$F,BASE!$A:$A,$B$3),0) -> 0.12726791 | G6: =SUM('Dashboard Calc'!$E$2:$E$11) -> 937 | J6: ='GRUPOS ZERADOS'!D16 -> 110 | M6: 46143 | N6: ='Dashboard Calc'!J6 -> 2940
M7: 46174 | N7: ='Dashboard Calc'!J7 -> 3007
M8: 46204 | N8: ='Dashboard Calc'!J8 -> 5021
A9: ="💡 Em "&TEXT($B$3,"mmm/aa")&", o Brasil registrou "&TEXT($A$6,"#.##0")&" trocas e "&TEXT($D$6,"0,0%")&" de Attachment. Há "&TEXT($J$6,"#.##0")&" de "&TEXT('GRUPOS ZERADOS'!B16,"#.##0")&" grupos a ativar ("&TEXT('GRUPOS ZERADOS'!F16,"0%")&" zerados), reforçando o potencial comercial." -> 💡 Em ago/26, o Brasil registrou 3.844 trocas e 12,7% de Attachment. Há 110 de 159 grupos a ativar (69% zerados), reforçando o potencial comercial. | M9: 46235 | N9: ='Dashboard Calc'!J9 -> 3844
M10: ='Dashboard Calc'!I10 -> 46266 | N10: ='Dashboard Calc'!J10
M11: ='Dashboard Calc'!I11 -> 46296 | N11: ='Dashboard Calc'!J11
M12: ='Dashboard Calc'!I12 -> 46327 | N12: ='Dashboard Calc'!J12
M13: ='Dashboard Calc'!I13 -> 46357 | N13: ='Dashboard Calc'!J13
A25: ⚠️ PRIORIDADES REGIONAIS — MENOR CONVERSÃO | H25: 🏆 TOP 5 PARCEIROS — ATTACHMENT
A26: REGIONAL | B26: ELEGÍVEIS | C26: ATIVOS | D26: CONVERSÃO | E26: GAP | F26: SINAL | H26: RANK | I26: PARCEIRO | J26: SELLOUT | K26: TROCAS | L26: ATTACHMENT
A27: {=_xlfn.TAKE(_xlfn.SORTBY(_xlfn.HSTACK('Dashboard Calc'!$A$2:$A$11,'Dashboard Calc'!$E$2:$E$11,'Dashboard Calc'!$F$2:$F$11,'Dashboard Calc'!$G$2:$G$11,'Dashboard Calc'!$E$2:$E$11-'Dashboard Calc'!$F$2:$F$11),'Dashboard Calc'!$G$2:$G$11,1),5)} -> NO | B27: 24 | C27: 2 | D27: 0.083333333 | E27: 22 | F27: =IF(D27<10%,"CRÍTICA",IF(D27<25%,"ATENÇÃO","ACOMPANHAR")) -> CRÍTICA | H27: {=_xlfn.TAKE('TOP 10 Parceiros'!$A$8:$E$17,5)} -> 1 | I27: FAJULUTI | J27: 1656 | K27: 494 | L27: 0.29830918
A28: MG | B28: 89 | C28: 30 | D28: 0.33707865 | E28: 59 | F28: =IF(D28<10%,"CRÍTICA",IF(D28<25%,"ATENÇÃO","ACOMPANHAR")) -> ACOMPANHAR | H28: 2 | I28: HS TELECOM | J28: 3700 | K28: 1065 | L28: 0.28783784
A29: NE | B29: 75 | C29: 27 | D29: 0.36 | E29: 48 | F29: =IF(D29<10%,"CRÍTICA",IF(D29<25%,"ATENÇÃO","ACOMPANHAR")) -> ACOMPANHAR | H29: 3 | I29: VIRACLARO | J29: 21 | K29: 6 | L29: 0.28571429
A30: BA/SE | B30: 61 | C30: 26 | D30: 0.42622951 | E30: 35 | F30: =IF(D30<10%,"CRÍTICA",IF(D30<25%,"ATENÇÃO","ACOMPANHAR")) -> ACOMPANHAR | H30: 4 | I30: DOM BARRETO COMERCIAL LTDA - ME | J30: 81 | K30: 21 | L30: 0.25925926
A31: CO | B31: 187 | C31: 88 | D31: 0.47058824 | E31: 99 | F31: =IF(D31<10%,"CRÍTICA",IF(D31<25%,"ATENÇÃO","ACOMPANHAR")) -> ACOMPANHAR | H31: 5 | I31: BANDEIRA | J31: 313 | K31: 74 | L31: 0.23642173

Sheet REGIONAL
A1: CANAL AA |CLARO TROCA |REGIONAL
D4: QTDE PDVS
A5: REGIONAL | B5: PDVs | C5: ELEGÍVEIS | D5: COM TROCAS | E5: ZERADO | F5: COBERTURA TOTAL | G5: ZERADOS / ELEGÍVEIS
A6: SP1 | B6: =COUNTIFS(PDVS!G:G,A6) -> 70 | C6: =COUNTIFS(PDVS!G:G,A6,PDVS!J:J,"SIM") -> 70 | D6: =COUNTIFS(PDVS!$X:$X,D$5,PDVS!$G:$G,$A6,PDVS!J:J,"SIM") -> 40 | E6: =COUNTIFS(PDVS!$X:$X,E$5,PDVS!$G:$G,$A6,PDVS!$J:$J,"SIM") -> 30 | F6: =D6/B6 -> 0.57142857 | G6: =IFERROR(E6/C6,0) -> 0.42857143
A7: SP2 | B7: =COUNTIFS(PDVS!G:G,A7) -> 180 | C7: =COUNTIFS(PDVS!G:G,A7,PDVS!J:J,"SIM") -> 170 | D7: =COUNTIFS(PDVS!$X:$X,D$5,PDVS!$G:$G,$A7,PDVS!J:J,"SIM") -> 110 | E7: =COUNTIFS(PDVS!$X:$X,E$5,PDVS!$G:$G,$A7,PDVS!$J:$J,"SIM") -> 60 | F7: =D7/B7 -> 0.61111111 | G7: =IFERROR(E7/C7,0) -> 0.35294118
A8: RJ/ES | B8: =COUNTIFS(PDVS!G:G,A8) -> 97 | C8: =COUNTIFS(PDVS!G:G,A8,PDVS!J:J,"SIM") -> 97 | D8: =COUNTIFS(PDVS!$X:$X,D$5,PDVS!$G:$G,$A8,PDVS!J:J,"SIM") -> 72 | E8: =COUNTIFS(PDVS!$X:$X,E$5,PDVS!$G:$G,$A8,PDVS!$J:$J,"SIM") -> 25 | F8: =D8/B8 -> 0.74226804 | G8: =IFERROR(E8/C8,0) -> 0.25773196
A9: MG | B9: =COUNTIFS(PDVS!G:G,A9) -> 93 | C9: =COUNTIFS(PDVS!G:G,A9,PDVS!J:J,"SIM") -> 89 | D9: =COUNTIFS(PDVS!$X:$X,D$5,PDVS!$G:$G,$A9,PDVS!J:J,"SIM") -> 30 | E9: =COUNTIFS(PDVS!$X:$X,E$5,PDVS!$G:$G,$A9,PDVS!$J:$J,"SIM") -> 59 | F9: =D9/B9 -> 0.32258065 | G9: =IFERROR(E9/C9,0) -> 0.66292135
A10: PR/SC | B10: =COUNTIFS(PDVS!G:G,A10) -> 88 | C10: =COUNTIFS(PDVS!G:G,A10,PDVS!J:J,"SIM") -> 85 | D10: =COUNTIFS(PDVS!$X:$X,D$5,PDVS!$G:$G,$A10,PDVS!J:J,"SIM") -> 49 | E10: =COUNTIFS(PDVS!$X:$X,E$5,PDVS!$G:$G,$A10,PDVS!$J:$J,"SIM") -> 36 | F10: =D10/B10 -> 0.55681818 | G10: =IFERROR(E10/C10,0) -> 0.42352941
A11: RS | B11: =COUNTIFS(PDVS!G:G,A11) -> 81 | C11: =COUNTIFS(PDVS!G:G,A11,PDVS!J:J,"SIM") -> 79 | D11: =COUNTIFS(PDVS!$X:$X,D$5,PDVS!$G:$G,$A11,PDVS!J:J,"SIM") -> 46 | E11: =COUNTIFS(PDVS!$X:$X,E$5,PDVS!$G:$G,$A11,PDVS!$J:$J,"SIM") -> 33 | F11: =D11/B11 -> 0.56790123 | G11: =IFERROR(E11/C11,0) -> 0.41772152
A12: CO | B12: =COUNTIFS(PDVS!G:G,A12) -> 197 | C12: =COUNTIFS(PDVS!G:G,A12,PDVS!J:J,"SIM") -> 187 | D12: =COUNTIFS(PDVS!$X:$X,D$5,PDVS!$G:$G,$A12,PDVS!J:J,"SIM") -> 88 | E12: =COUNTIFS(PDVS!$X:$X,E$5,PDVS!$G:$G,$A12,PDVS!$J:$J,"SIM") -> 99 | F12: =D12/B12 -> 0.44670051 | G12: =IFERROR(E12/C12,0) -> 0.52941176
A13: BA/SE | B13: =COUNTIFS(PDVS!G:G,A13) -> 62 | C13: =COUNTIFS(PDVS!G:G,A13,PDVS!J:J,"SIM") -> 61 | D13: =COUNTIFS(PDVS!$X:$X,D$5,PDVS!$G:$G,$A13,PDVS!J:J,"SIM") -> 26 | E13: =COUNTIFS(PDVS!$X:$X,E$5,PDVS!$G:$G,$A13,PDVS!$J:$J,"SIM") -> 35 | F13: =D13/B13 -> 0.41935484 | G13: =IFERROR(E13/C13,0) -> 0.57377049
A14: NE | B14: =COUNTIFS(PDVS!G:G,A14) -> 96 | C14: =COUNTIFS(PDVS!G:G,A14,PDVS!J:J,"SIM") -> 75 | D14: =COUNTIFS(PDVS!$X:$X,D$5,PDVS!$G:$G,$A14,PDVS!J:J,"SIM") -> 27 | E14: =COUNTIFS(PDVS!$X:$X,E$5,PDVS!$G:$G,$A14,PDVS!$J:$J,"SIM") -> 48 | F14: =D14/B14 -> 0.28125 | G14: =IFERROR(E14/C14,0) -> 0.64
A15: NO | B15: =COUNTIFS(PDVS!G:G,A15) -> 43 | C15: =COUNTIFS(PDVS!G:G,A15,PDVS!J:J,"SIM") -> 24 | D15: =COUNTIFS(PDVS!$X:$X,D$5,PDVS!$G:$G,$A15,PDVS!J:J,"SIM") -> 2 | E15: =COUNTIFS(PDVS!$X:$X,E$5,PDVS!$G:$G,$A15,PDVS!$J:$J,"SIM") -> 22 | F15: =D15/B15 -> 0.046511628 | G15: =IFERROR(E15/C15,0) -> 0.91666667
A16: BR | B16: =SUM(B6:B15) -> 1007 | C16: =SUM(C6:C15) -> 937 | D16: =SUM(D6:D15) -> 490 | E16: =SUM(E6:E15) -> 447 | F16: =D16/B16 -> 0.48659384 | G16: =IFERROR(E16/C16,0) -> 0.47705443
C19: COM BOOST
C20: SEM REPASSE

Sheet TOP 10 Parceiros
A1: TOP 10 PARCEIROS BRASIL — ATTACHMENT | H1: Meses disponíveis
A2: Visão mensal consolidada por Grupo Rede, somando todas as regionais e sem corte mínimo de Sellout. | H2: {=_xlfn._xlws.SORT(_xlfn.UNIQUE(_xlfn._xlws.FILTER(BASE!$A$2:$A$10000,BASE!$A$2:$A$10000<>"")))} -> 46023
A3: MÊS | B3: 46235 | C3: LÍDER | D3: =IFERROR(INDEX(_xlfn.ANCHORARRAY($B$8),1,1),"") -> FAJULUTI | G3: =IFERROR(INDEX(_xlfn.ANCHORARRAY($B$8),1,4),0) -> 0.29830918 | H3: 46054
H4: 46082
A5: ="Em "&TEXT($B$3,"mmm")&"/"&TEXT(MOD(YEAR($B$3),100),"00")&", "&INDEX(_xlfn.ANCHORARRAY($B$8),1,1)&" lidera o Brasil com "&TEXT(INDEX(_xlfn.ANCHORARRAY($B$8),1,4),"0,0%")&" de Attachment: "&FIXED(INDEX(_xlfn.ANCHORARRAY($B$8),1,3),0,FALSE)&" Claro Trocas sobre "&FIXED(INDEX(_xlfn.ANCHORARRAY($B$8),1,2),0,FALSE)&" aparelhos de Sellout." -> Em ago/26, FAJULUTI lidera o Brasil com 29,8% de Attachment: 494 Claro Trocas sobre 1.656 aparelhos de Sellout. | H5: 46113
A6: RANKING NACIONAL | H6: 46143
A7: RANK | B7: PARCEIRO / GRUPO REDE | C7: SELLOUT | D7: CLARO TROCA | E7: ATTACHMENT | F7: Nº REGIONAIS | G7: REGIONAIS | H7: 46174
A8: {=_xlfn.SEQUENCE(ROWS(_xlfn.ANCHORARRAY(B8)))} -> 1 | B8: {=_xlfn.LET(_xlpm.m,$B$3,_xlpm.gr,IFERROR(BASE!$J$2:$J$10000,""),_xlpm.g,_xlfn.UNIQUE(_xlfn._xlws.FILTER(_xlpm.gr,(BASE!$A$2:$A$10000=_xlpm.m)*(_xlpm.gr<>""))),_xlpm.s,_xlfn.MAP(_xlpm.g,_xlfn.LAMBDA(_xlpm.x,SUMPRODUCT((BASE!$A$2:$A$10000=_xlpm.m)*(_xlpm.gr=_xlpm.x)*IFERROR(BASE!$F$2:$F$10000,0)))),_xlpm.t,_xlfn.MAP(_xlpm.g,_xlfn.LAMBDA(_xlpm.x,SUMPRODUCT((BASE!$A$2:$A$10000=_xlpm.m)*(_xlpm.gr=_xlpm.x)*IFERROR(BASE!$G$2:$G$10000,0)))),_xlpm.a,IFERROR(_xlpm.t/_xlpm.s,0),_xlfn.TAKE(_xlfn.SORTBY(_xlfn.HSTACK(_xlpm.g,_xlpm.s,_xlpm.t,_xlpm.a),_xlpm.a,-1,_xlpm.t,-1),MIN(10,ROWS(_xlpm.g))))} -> FAJULUTI | C8: 1656 | D8: 494 | E8: 0.29830918 | F8: {=IF(B8="","",COUNTA(_xlfn.UNIQUE(_xlfn._xlws.FILTER(IFERROR(BASE!$L$2:$L$10000,""),(BASE!$A$2:$A$10000=$B$3)*(IFERROR(BASE!$J$2:$J$10000,"")=B8)*(IFERROR(BASE!$L$2:$L$10000,"")<>"")))))} -> 2 | G8: {=IF(B8="","",_xlfn.TEXTJOIN(", ",TRUE,_xlfn._xlws.SORT(_xlfn.UNIQUE(_xlfn._xlws.FILTER(IFERROR(BASE!$L$2:$L$10000,""),(BASE!$A$2:$A$10000=$B$3)*(IFERROR(BASE!$J$2:$J$10000,"")=B8)*(IFERROR(BASE!$L$2:$L$10000,"")<>""))))))} -> MG, RJ/ES | H8: 46204
A9: 2 | B9: HS TELECOM | C9: 3700 | D9: 1065 | E9: 0.28783784 | F9: {=IF(B9="","",COUNTA(_xlfn.UNIQUE(_xlfn._xlws.FILTER(IFERROR(BASE!$L$2:$L$10000,""),(BASE!$A$2:$A$10000=$B$3)*(IFERROR(BASE!$J$2:$J$10000,"")=B9)*(IFERROR(BASE!$L$2:$L$10000,"")<>"")))))} -> 3 | G9: {=IF(B9="","",_xlfn.TEXTJOIN(", ",TRUE,_xlfn._xlws.SORT(_xlfn.UNIQUE(_xlfn._xlws.FILTER(IFERROR(BASE!$L$2:$L$10000,""),(BASE!$A$2:$A$10000=$B$3)*(IFERROR(BASE!$J$2:$J$10000,"")=B9)*(IFERROR(BASE!$L$2:$L$10000,"")<>""))))))} -> BA/SE, RJ/ES, SP2 | H9: 46235
A10: 3 | B10: VIRACLARO | C10: 21 | D10: 6 | E10: 0.28571429 | F10: {=IF(B10="","",COUNTA(_xlfn.UNIQUE(_xlfn._xlws.FILTER(IFERROR(BASE!$L$2:$L$10000,""),(BASE!$A$2:$A$10000=$B$3)*(IFERROR(BASE!$J$2:$J$10000,"")=B10)*(IFERROR(BASE!$L$2:$L$10000,"")<>"")))))} -> 1 | G10: {=IF(B10="","",_xlfn.TEXTJOIN(", ",TRUE,_xlfn._xlws.SORT(_xlfn.UNIQUE(_xlfn._xlws.FILTER(IFERROR(BASE!$L$2:$L$10000,""),(BASE!$A$2:$A$10000=$B$3)*(IFERROR(BASE!$J$2:$J$10000,"")=B10)*(IFERROR(BASE!$L$2:$L$10000,"")<>""))))))} -> SP2
A11: 4 | B11: DOM BARRETO COMERCIAL LTDA - ME | C11: 81 | D11: 21 | E11: 0.25925926 | F11: {=IF(B11="","",COUNTA(_xlfn.UNIQUE(_xlfn._xlws.FILTER(IFERROR(BASE!$L$2:$L$10000,""),(BASE!$A$2:$A$10000=$B$3)*(IFERROR(BASE!$J$2:$J$10000,"")=B11)*(IFERROR(BASE!$L$2:$L$10000,"")<>"")))))} -> 1 | G11: {=IF(B11="","",_xlfn.TEXTJOIN(", ",TRUE,_xlfn._xlws.SORT(_xlfn.UNIQUE(_xlfn._xlws.FILTER(IFERROR(BASE!$L$2:$L$10000,""),(BASE!$A$2:$A$10000=$B$3)*(IFERROR(BASE!$J$2:$J$10000,"")=B11)*(IFERROR(BASE!$L$2:$L$10000,"")<>""))))))} -> SP2
A12: 5 | B12: BANDEIRA | C12: 313 | D12: 74 | E12: 0.23642173 | F12: {=IF(B12="","",COUNTA(_xlfn.UNIQUE(_xlfn._xlws.FILTER(IFERROR(BASE!$L$2:$L$10000,""),(BASE!$A$2:$A$10000=$B$3)*(IFERROR(BASE!$J$2:$J$10000,"")=B12)*(IFERROR(BASE!$L$2:$L$10000,"")<>"")))))} -> 1 | G12: {=IF(B12="","",_xlfn.TEXTJOIN(", ",TRUE,_xlfn._xlws.SORT(_xlfn.UNIQUE(_xlfn._xlws.FILTER(IFERROR(BASE!$L$2:$L$10000,""),(BASE!$A$2:$A$10000=$B$3)*(IFERROR(BASE!$J$2:$J$10000,"")=B12)*(IFERROR(BASE!$L$2:$L$10000,"")<>""))))))} -> PR/SC
A13: 6 | B13: R & R HIPER COMERCIO LTDA | C13: 247 | D13: 51 | E13: 0.20647773 | F13: {=IF(B13="","",COUNTA(_xlfn.UNIQUE(_xlfn._xlws.FILTER(IFERROR(BASE!$L$2:$L$10000,""),(BASE!$A$2:$A$10000=$B$3)*(IFERROR(BASE!$J$2:$J$10000,"")=B13)*(IFERROR(BASE!$L$2:$L$10000,"")<>"")))))} -> 1 | G13: {=IF(B13="","",_xlfn.TEXTJOIN(", ",TRUE,_xlfn._xlws.SORT(_xlfn.UNIQUE(_xlfn._xlws.FILTER(IFERROR(BASE!$L$2:$L$10000,""),(BASE!$A$2:$A$10000=$B$3)*(IFERROR(BASE!$J$2:$J$10000,"")=B13)*(IFERROR(BASE!$L$2:$L$10000,"")<>""))))))} -> NE
A14: 7 | B14: ADESIENE NUNES MACHADO - ME | C14: 96 | D14: 19 | E14: 0.19791667 | F14: {=IF(B14="","",COUNTA(_xlfn.UNIQUE(_xlfn._xlws.FILTER(IFERROR(BASE!$L$2:$L$10000,""),(BASE!$A$2:$A$10000=$B$3)*(IFERROR(BASE!$J$2:$J$10000,"")=B14)*(IFERROR(BASE!$L$2:$L$10000,"")<>"")))))} -> 1 | G14: {=IF(B14="","",_xlfn.TEXTJOIN(", ",TRUE,_xlfn._xlws.SORT(_xlfn.UNIQUE(_xlfn._xlws.FILTER(IFERROR(BASE!$L$2:$L$10000,""),(BASE!$A$2:$A$10000=$B$3)*(IFERROR(BASE!$J$2:$J$10000,"")=B14)*(IFERROR(BASE!$L$2:$L$10000,"")<>""))))))} -> SP2
A15: 8 | B15: HARCOS COMERCIO E SERVICOS LTDA - EPP | C15: 1067 | D15: 210 | E15: 0.1968135 | F15: {=IF(B15="","",COUNTA(_xlfn.UNIQUE(_xlfn._xlws.FILTER(IFERROR(BASE!$L$2:$L$10000,""),(BASE!$A$2:$A$10000=$B$3)*(IFERROR(BASE!$J$2:$J$10000,"")=B15)*(IFERROR(BASE!$L$2:$L$10000,"")<>"")))))} -> 1 | G15: {=IF(B15="","",_xlfn.TEXTJOIN(", ",TRUE,_xlfn._xlws.SORT(_xlfn.UNIQUE(_xlfn._xlws.FILTER(IFERROR(BASE!$L$2:$L$10000,""),(BASE!$A$2:$A$10000=$B$3)*(IFERROR(BASE!$J$2:$J$10000,"")=B15)*(IFERROR(BASE!$L$2:$L$10000,"")<>""))))))} -> NE
A16: 9 | B16: CELNET COMERCIO E SERVICOS DE TELEFONIA LTDA ME | C16: 1186 | D16: 212 | E16: 0.17875211 | F16: {=IF(B16="","",COUNTA(_xlfn.UNIQUE(_xlfn._xlws.FILTER(IFERROR(BASE!$L$2:$L$10000,""),(BASE!$A$2:$A$10000=$B$3)*(IFERROR(BASE!$J$2:$J$10000,"")=B16)*(IFERROR(BASE!$L$2:$L$10000,"")<>"")))))} -> 1 | G16: {=IF(B16="","",_xlfn.TEXTJOIN(", ",TRUE,_xlfn._xlws.SORT(_xlfn.UNIQUE(_xlfn._xlws.FILTER(IFERROR(BASE!$L$2:$L$10000,""),(BASE!$A$2:$A$10000=$B$3)*(IFERROR(BASE!$J$2:$J$10000,"")=B16)*(IFERROR(BASE!$L$2:$L$10000,"")<>""))))))} -> CO
A17: 10 | B17: FLEX CELL | C17: 1904 | D17: 323 | E17: 0.16964286 | F17: {=IF(B17="","",COUNTA(_xlfn.UNIQUE(_xlfn._xlws.FILTER(IFERROR(BASE!$L$2:$L$10000,""),(BASE!$A$2:$A$10000=$B$3)*(IFERROR(BASE!$J$2:$J$10000,"")=B17)*(IFERROR(BASE!$L$2:$L$10000,"")<>"")))))} -> 3 | G17: {=IF(B17="","",_xlfn.TEXTJOIN(", ",TRUE,_xlfn._xlws.SORT(_xlfn.UNIQUE(_xlfn._xlws.FILTER(IFERROR(BASE!$L$2:$L$10000,""),(BASE!$A$2:$A$10000=$B$3)*(IFERROR(BASE!$J$2:$J$10000,"")=B17)*(IFERROR(BASE!$L$2:$L$10000,"")<>""))))))} -> NO, SP1, SP2

Sheet GRUPOS ZERADOS
A1: CANAL AA |CLARO TROCA |GRUPOS REDES
C4: GRUPOS REDES
A5: REG | B5: GRUPOS | C5: COM TROCAS | D5: ZERADO | E5: % COM VENDAS | F5: % ZERADOS
A6: SP1 | B6: =COUNTIFS(GRUPOS!C:C,A6,GRUPOS!$F:$F,"SIM") -> 9 | C6: =COUNTIFS(GRUPOS!$T:$T,$C$5,GRUPOS!$C:$C,$A6,GRUPOS!$F:$F,"SIM") -> 4 | D6: =COUNTIFS(GRUPOS!$T:$T,$D$5,GRUPOS!$C:$C,$A6,GRUPOS!F:F,"SIM") -> 5 | E6: =C6/B6 -> 0.44444444 | F6: =D6/B6 -> 0.55555556
A7: SP2 | B7: =COUNTIFS(GRUPOS!C:C,A7,GRUPOS!$F:$F,"SIM") -> 16 | C7: =COUNTIFS(GRUPOS!$T:$T,$C$5,GRUPOS!$C:$C,$A7,GRUPOS!F:F,"SIM") -> 10 | D7: =COUNTIFS(GRUPOS!$T:$T,$D$5,GRUPOS!$C:$C,$A7,GRUPOS!F:F,"SIM") -> 6 | E7: =C7/B7 -> 0.625 | F7: =D7/B7 -> 0.375
A8: RJ/ES | B8: =COUNTIFS(GRUPOS!C:C,A8,GRUPOS!$F:$F,"SIM") -> 10 | C8: =COUNTIFS(GRUPOS!$T:$T,$C$5,GRUPOS!$C:$C,$A8,GRUPOS!F:F,"SIM") -> 6 | D8: =COUNTIFS(GRUPOS!$T:$T,$D$5,GRUPOS!$C:$C,$A8,GRUPOS!F:F,"SIM") -> 4 | E8: =C8/B8 -> 0.6 | F8: =D8/B8 -> 0.4
A9: MG | B9: =COUNTIFS(GRUPOS!C:C,A9,GRUPOS!$F:$F,"SIM") -> 22 | C9: =COUNTIFS(GRUPOS!$T:$T,$C$5,GRUPOS!$C:$C,$A9,GRUPOS!F:F,"SIM") -> 4 | D9: =COUNTIFS(GRUPOS!$T:$T,$D$5,GRUPOS!$C:$C,$A9,GRUPOS!F:F,"SIM") -> 18 | E9: =C9/B9 -> 0.18181818 | F9: =D9/B9 -> 0.81818182
A10: PR/SC | B10: =COUNTIFS(GRUPOS!C:C,A10,GRUPOS!$F:$F,"SIM") -> 5 | C10: =COUNTIFS(GRUPOS!$T:$T,$C$5,GRUPOS!$C:$C,$A10,GRUPOS!F:F,"SIM") -> 4 | D10: =COUNTIFS(GRUPOS!$T:$T,$D$5,GRUPOS!$C:$C,$A10,GRUPOS!F:F,"SIM") -> 1 | E10: =C10/B10 -> 0.8 | F10: =D10/B10 -> 0.2
A11: RS | B11: =COUNTIFS(GRUPOS!C:C,A11,GRUPOS!$F:$F,"SIM") -> 5 | C11: =COUNTIFS(GRUPOS!$T:$T,$C$5,GRUPOS!$C:$C,$A11,GRUPOS!F:F,"SIM") -> 4 | D11: =COUNTIFS(GRUPOS!$T:$T,$D$5,GRUPOS!$C:$C,$A11,GRUPOS!F:F,"SIM") -> 1 | E11: =C11/B11 -> 0.8 | F11: =D11/B11 -> 0.2
A12: CO | B12: =COUNTIFS(GRUPOS!C:C,A12,GRUPOS!$F:$F,"SIM") -> 39 | C12: =COUNTIFS(GRUPOS!$T:$T,$C$5,GRUPOS!$C:$C,$A12,GRUPOS!F:F,"SIM") -> 7 | D12: =COUNTIFS(GRUPOS!$T:$T,$D$5,GRUPOS!$C:$C,$A12,GRUPOS!F:F,"SIM") -> 32 | E12: =C12/B12 -> 0.17948718 | F12: =D12/B12 -> 0.82051282
A13: BA/SE | B13: =COUNTIFS(GRUPOS!C:C,A13,GRUPOS!$F:$F,"SIM") -> 24 | C13: =COUNTIFS(GRUPOS!$T:$T,$C$5,GRUPOS!$C:$C,$A13,GRUPOS!F:F,"SIM") -> 5 | D13: =COUNTIFS(GRUPOS!$T:$T,$D$5,GRUPOS!$C:$C,$A13,GRUPOS!F:F,"SIM") -> 19 | E13: =C13/B13 -> 0.20833333 | F13: =D13/B13 -> 0.79166667
A14: NE | B14: =COUNTIFS(GRUPOS!C:C,A14,GRUPOS!$F:$F,"SIM") -> 17 | C14: =COUNTIFS(GRUPOS!$T:$T,$C$5,GRUPOS!$C:$C,$A14,GRUPOS!F:F,"SIM") -> 3 | D14: =COUNTIFS(GRUPOS!$T:$T,$D$5,GRUPOS!$C:$C,$A14,GRUPOS!F:F,"SIM") -> 14 | E14: =C14/B14 -> 0.17647059 | F14: =D14/B14 -> 0.82352941
A15: NO | B15: =COUNTIFS(GRUPOS!C:C,A15,GRUPOS!$F:$F,"SIM") -> 12 | C15: =COUNTIFS(GRUPOS!$T:$T,$C$5,GRUPOS!$C:$C,$A15,GRUPOS!F:F,"SIM") -> 2 | D15: =COUNTIFS(GRUPOS!$T:$T,$D$5,GRUPOS!$C:$C,$A15,GRUPOS!F:F,"SIM") -> 10 | E15: =C15/B15 -> 0.16666667 | F15: =D15/B15 -> 0.83333333
A16: BR | B16: =SUM(B6:B15) -> 159 | C16: =SUM(C6:C15) -> 49 | D16: =SUM(D6:D15) -> 110 | E16: =C16/B16 -> 0.3081761 | F16: =D16/B16 -> 0.6918239

Sheet GRUPOS
B6: GRUPOS | C6: REGIONAIS | D6: REPASSES | E6: BOOST LIBERADOS | F6: ELEGÍVEL | G6: 46023 | H6: 46054 | I6: 46082 | J6: 46113 | K6: 46143 | L6: 46174 | M6: 46204 | N6: 46235 | O6: 46266 | P6: 46296 | Q6: 46327 | R6: 46357 | T6: STATUS
B7: A C DE OLIVEIRA PINHEIRO & FILHO LTDA. | C7: NE | D7: =COUNTIFS(PDVS!H:H,"SIM",PDVS!C:C,B7) -> 0 | E7: =COUNTIFS(PDVS!C:C,B7,PDVS!I:I,"SIM") -> 0 | F7: =IF(AND(D7=0,E7>=1),"Sim",IF(D7>=1,"Não",IF(AND(D7=0,E7=0),"Sim",""))) -> Sim | G7: =SUMIFS(BASE!$G:$G,BASE!$L:$L,$C7,BASE!$J:$J,$B7,BASE!$A:$A,G$6) -> 0 | H7: =SUMIFS(BASE!$G:$G,BASE!$L:$L,$C7,BASE!$J:$J,$B7,BASE!$A:$A,H$6) -> 0 | I7: =SUMIFS(BASE!$G:$G,BASE!$L:$L,$C7,BASE!$J:$J,$B7,BASE!$A:$A,I$6) -> 0 | J7: =SUMIFS(BASE!$G:$G,BASE!$L:$L,$C7,BASE!$J:$J,$B7,BASE!$A:$A,J$6) -> 0 | K7: =SUMIFS(BASE!$G:$G,BASE!$L:$L,$C7,BASE!$J:$J,$B7,BASE!$A:$A,K$6) -> 0 | L7: =SUMIFS(BASE!$G:$G,BASE!$L:$L,$C7,BASE!$J:$J,$B7,BASE!$A:$A,L$6) -> 0 | M7: =SUMIFS(BASE!$G:$G,BASE!$L:$L,$C7,BASE!$J:$J,$B7,BASE!$A:$A,M$6) -> 0 | N7: =SUMIFS(BASE!$G:$G,BASE!$L:$L,$C7,BASE!$J:$J,$B7,BASE!$A:$A,N$6) -> 0 | ... R7: =SUMIFS(BASE!$G:$G,BASE!$L:$L,$C7,BASE!$J:$J,$B7,BASE!$A:$A,R$6) -> 0 | T7: =IF(AND(N7=0),"ZERADO","COM TROCAS") -> ZERADO
B8: A PLAY S COMERCIO E SERVICOS LTDA | C8: BA/SE | D8: =COUNTIFS(PDVS!H:H,"SIM",PDVS!C:C,B8) -> 0 | E8: =COUNTIFS(PDVS!C:C,B8,PDVS!I:I,"SIM") -> 1 | F8: =IF(AND(D8=0,E8>=1),"Sim",IF(D8>=1,"Não",IF(AND(D8=0,E8=0),"Sim",""))) -> Sim | G8: =SUMIFS(BASE!$G:$G,BASE!$L:$L,$C8,BASE!$J:$J,$B8,BASE!$A:$A,G$6) -> 0 | H8: =SUMIFS(BASE!$G:$G,BASE!$L:$L,$C8,BASE!$J:$J,$B8,BASE!$A:$A,H$6) -> 0 | I8: =SUMIFS(BASE!$G:$G,BASE!$L:$L,$C8,BASE!$J:$J,$B8,BASE!$A:$A,I$6) -> 0 | J8: =SUMIFS(BASE!$G:$G,BASE!$L:$L,$C8,BASE!$J:$J,$B8,BASE!$A:$A,J$6) -> 0 | K8: =SUMIFS(BASE!$G:$G,BASE!$L:$L,$C8,BASE!$J:$J,$B8,BASE!$A:$A,K$6) -> 0 | L8: =SUMIFS(BASE!$G:$G,BASE!$L:$L,$C8,BASE!$J:$J,$B8,BASE!$A:$A,L$6) -> 0 | M8: =SUMIFS(BASE!$G:$G,BASE!$L:$L,$C8,BASE!$J:$J,$B8,BASE!$A:$A,M$6) -> 0 | N8: =SUMIFS(BASE!$G:$G,BASE!$L:$L,$C8,BASE!$J:$J,$B8,BASE!$A:$A,N$6) -> 0 | ... R8: =SUMIFS(BASE!$G:$G,BASE!$L:$L,$C8,BASE!$J:$J,$B8,BASE!$A:$A,R$6) -> 0 | T8: =IF(AND(N8=0),"ZERADO","COM TROCAS") -> ZERADO
B9: A. L. DE OLIVEIRA & CIA LTDA | C9: CO | D9: =COUNTIFS(PDVS!H:H,"SIM",PDVS!C:C,B9) -> 0 | E9: =COUNTIFS(PDVS!C:C,B9,PDVS!I:I,"SIM") -> 1 | F9: =IF(AND(D9=0,E9>=1),"Sim",IF(D9>=1,"Não",IF(AND(D9=0,E9=0),"Sim",""))) -> Sim | G9: =SUMIFS(BASE!$G:$G,BASE!$L:$L,$C9,BASE!$J:$J,$B9,BASE!$A:$A,G$6) -> 0 | H9: =SUMIFS(BASE!$G:$G,BASE!$L:$L,$C9,BASE!$J:$J,$B9,BASE!$A:$A,H$6) -> 0 | I9: =SUMIFS(BASE!$G:$G,BASE!$L:$L,$C9,BASE!$J:$J,$B9,BASE!$A:$A,I$6) -> 0 | J9: =SUMIFS(BASE!$G:$G,BASE!$L:$L,$C9,BASE!$J:$J,$B9,BASE!$A:$A,J$6) -> 0 | K9: =SUMIFS(BASE!$G:$G,BASE!$L:$L,$C9,BASE!$J:$J,$B9,BASE!$A:$A,K$6) -> 0 | L9: =SUMIFS(BASE!$G:$G,BASE!$L:$L,$C9,BASE!$J:$J,$B9,BASE!$A:$A,L$6) -> 0 | M9: =SUMIFS(BASE!$G:$G,BASE!$L:$L,$C9,BASE!$J:$J,$B9,BASE!$A:$A,M$6) -> 0 | N9: =SUMIFS(BASE!$G:$G,BASE!$L:$L,$C9,BASE!$J:$J,$B9,BASE!$A:$A,N$6) -> 0 | ... R9: =SUMIFS(BASE!$G:$G,BASE!$L:$L,$C9,BASE!$J:$J,$B9,BASE!$A:$A,R$6) -> 0 | T9: =IF(AND(N9=0),"ZERADO","COM TROCAS") -> ZERADO
B10: AC BAYLONGUE | C10: SP1 | D10: =COUNTIFS(PDVS!H:H,"SIM",PDVS!C:C,B10) -> 0 | E10: =COUNTIFS(PDVS!C:C,B10,PDVS!I:I,"SIM") -> 1 | F10: =IF(AND(D10=0,E10>=1),"Sim",IF(D10>=1,"Não",IF(AND(D10=0,E10=0),"Sim",""))) -> Sim | G10: =SUMIFS(BASE!$G:$G,BASE!$L:$L,$C10,BASE!$J:$J,$B10,BASE!$A:$A,G$6) -> 0 | H10: =SUMIFS(BASE!$G:$G,BASE!$L:$L,$C10,BASE!$J:$J,$B10,BASE!$A:$A,H$6) -> 0 | I10: =SUMIFS(BASE!$G:$G,BASE!$L:$L,$C10,BASE!$J:$J,$B10,BASE!$A:$A,I$6) -> 0 | J10: =SUMIFS(BASE!$G:$G,BASE!$L:$L,$C10,BASE!$J:$J,$B10,BASE!$A:$A,J$6) -> 0 | K10: =SUMIFS(BASE!$G:$G,BASE!$L:$L,$C10,BASE!$J:$J,$B10,BASE!$A:$A,K$6) -> 0 | L10: =SUMIFS(BASE!$G:$G,BASE!$L:$L,$C10,BASE!$J:$J,$B10,BASE!$A:$A,L$6) -> 0 | M10: =SUMIFS(BASE!$G:$G,BASE!$L:$L,$C10,BASE!$J:$J,$B10,BASE!$A:$A,M$6) -> 0 | N10: =SUMIFS(BASE!$G:$G,BASE!$L:$L,$C10,BASE!$J:$J,$B10,BASE!$A:$A,N$6) -> 0 | ... R10: =SUMIFS(BASE!$G:$G,BASE!$L:$L,$C10,BASE!$J:$J,$B10,BASE!$A:$A,R$6) -> 0 | T10: =IF(AND(N10=0),"ZERADO","COM TROCAS") -> ZERADO
B11: ALEXANDRE CISOTTO LAN HOUSE E TELECOMUNICACOES ME | C11: SP1 | D11: =COUNTIFS(PDVS!H:H,"SIM",PDVS!C:C,B11) -> 0 | E11: =COUNTIFS(PDVS!C:C,B11,PDVS!I:I,"SIM") -> 1 | F11: =IF(AND(D11=0,E11>=1),"Sim",IF(D11>=1,"Não",IF(AND(D11=0,E11=0),"Sim",""))) -> Sim | G11: =SUMIFS(BASE!$G:$G,BASE!$L:$L,$C11,BASE!$J:$J,$B11,BASE!$A:$A,G$6) -> 0 | H11: =SUMIFS(BASE!$G:$G,BASE!$L:$L,$C11,BASE!$J:$J,$B11,BASE!$A:$A,H$6) -> 0 | I11: =SUMIFS(BASE!$G:$G,BASE!$L:$L,$C11,BASE!$J:$J,$B11,BASE!$A:$A,I$6) -> 0 | J11: =SUMIFS(BASE!$G:$G,BASE!$L:$L,$C11,BASE!$J:$J,$B11,BASE!$A:$A,J$6) -> 0 | K11: =SUMIFS(BASE!$G:$G,BASE!$L:$L,$C11,BASE!$J:$J,$B11,BASE!$A:$A,K$6) -> 0 | L11: =SUMIFS(BASE!$G:$G,BASE!$L:$L,$C11,BASE!$J:$J,$B11,BASE!$A:$A,L$6) -> 0 | M11: =SUMIFS(BASE!$G:$G,BASE!$L:$L,$C11,BASE!$J:$J,$B11,BASE!$A:$A,M$6) -> 0 | N11: =SUMIFS(BASE!$G:$G,BASE!$L:$L,$C11,BASE!$J:$J,$B11,BASE!$A:$A,N$6) -> 0 | ... R11: =SUMIFS(BASE!$G:$G,BASE!$L:$L,$C11,BASE!$J:$J,$B11,BASE!$A:$A,R$6) -> 0 | T11: =IF(AND(N11=0),"ZERADO","COM TROCAS") -> ZERADO
B12: ALFA CELULAR LTDA | C12: MG | D12: =COUNTIFS(PDVS!H:H,"SIM",PDVS!C:C,B12) -> 1 | E12: =COUNTIFS(PDVS!C:C,B12,PDVS!I:I,"SIM") -> 3 | F12: =IF(AND(D12=0,E12>=1),"Sim",IF(D12>=1,"Não",IF(AND(D12=0,E12=0),"Sim",""))) -> Não | G12: =SUMIFS(BASE!$G:$G,BASE!$L:$L,$C12,BASE!$J:$J,$B12,BASE!$A:$A,G$6) -> 0 | H12: =SUMIFS(BASE!$G:$G,BASE!$L:$L,$C12,BASE!$J:$J,$B12,BASE!$A:$A,H$6) -> 0 | I12: =SUMIFS(BASE!$G:$G,BASE!$L:$L,$C12,BASE!$J:$J,$B12,BASE!$A:$A,I$6) -> 0 | J12: =SUMIFS(BASE!$G:$G,BASE!$L:$L,$C12,BASE!$J:$J,$B12,BASE!$A:$A,J$6) -> 0 | K12: =SUMIFS(BASE!$G:$G,BASE!$L:$L,$C12,BASE!$J:$J,$B12,BASE!$A:$A,K$6) -> 0 | L12: =SUMIFS(BASE!$G:$G,BASE!$L:$L,$C12,BASE!$J:$J,$B12,BASE!$A:$A,L$6) -> 0 | M12: =SUMIFS(BASE!$G:$G,BASE!$L:$L,$C12,BASE!$J:$J,$B12,BASE!$A:$A,M$6) -> 0 | N12: =SUMIFS(BASE!$G:$G,BASE!$L:$L,$C12,BASE!$J:$J,$B12,BASE!$A:$A,N$6) -> 0 | ... R12: =SUMIFS(BASE!$G:$G,BASE!$L:$L,$C12,BASE!$J:$J,$B12,BASE!$A:$A,R$6) -> 0 | T12: =IF(AND(N12=0),"ZERADO","COM TROCAS") -> ZERADO
B13: AM3 TELECOM LTDA | C13: NO | D13: =COUNTIFS(PDVS!H:H,"SIM",PDVS!C:C,B13) -> 0 | E13: =COUNTIFS(PDVS!C:C,B13,PDVS!I:I,"SIM") -> 0 | F13: =IF(AND(D13=0,E13>=1),"Sim",IF(D13>=1,"Não",IF(AND(D13=0,E13=0),"Sim",""))) -> Sim | G13: =SUMIFS(BASE!$G:$G,BASE!$L:$L,$C13,BASE!$J:$J,$B13,BASE!$A:$A,G$6) -> 0 | H13: =SUMIFS(BASE!$G:$G,BASE!$L:$L,$C13,BASE!$J:$J,$B13,BASE!$A:$A,H$6) -> 0 | I13: =SUMIFS(BASE!$G:$G,BASE!$L:$L,$C13,BASE!$J:$J,$B13,BASE!$A:$A,I$6) -> 0 | J13: =SUMIFS(BASE!$G:$G,BASE!$L:$L,$C13,BASE!$J:$J,$B13,BASE!$A:$A,J$6) -> 0 | K13: =SUMIFS(BASE!$G:$G,BASE!$L:$L,$C13,BASE!$J:$J,$B13,BASE!$A:$A,K$6) -> 0 | L13: =SUMIFS(BASE!$G:$G,BASE!$L:$L,$C13,BASE!$J:$J,$B13,BASE!$A:$A,L$6) -> 0 | M13: =SUMIFS(BASE!$G:$G,BASE!$L:$L,$C13,BASE!$J:$J,$B13,BASE!$A:$A,M$6) -> 0 | N13: =SUMIFS(BASE!$G:$G,BASE!$L:$L,$C13,BASE!$J:$J,$B13,BASE!$A:$A,N$6) -> 0 | ... R13: =SUMIFS(BASE!$G:$G,BASE!$L:$L,$C13,BASE!$J:$J,$B13,BASE!$A:$A,R$6) -> 0 | T13: =IF(AND(N13=0),"ZERADO","COM TROCAS") -> ZERADO
B14: AMOS MUNIZ CORREIA - ME | C14: CO | D14: =COUNTIFS(PDVS!H:H,"SIM",PDVS!C:C,B14) -> 0 | E14: =COUNTIFS(PDVS!C:C,B14,PDVS!I:I,"SIM") -> 1 | F14: =IF(AND(D14=0,E14>=1),"Sim",IF(D14>=1,"Não",IF(AND(D14=0,E14=0),"Sim",""))) -> Sim | G14: =SUMIFS(BASE!$G:$G,BASE!$L:$L,$C14,BASE!$J:$J,$B14,BASE!$A:$A,G$6) -> 0 | H14: =SUMIFS(BASE!$G:$G,BASE!$L:$L,$C14,BASE!$J:$J,$B14,BASE!$A:$A,H$6) -> 0 | I14: =SUMIFS(BASE!$G:$G,BASE!$L:$L,$C14,BASE!$J:$J,$B14,BASE!$A:$A,I$6) -> 0 | J14: =SUMIFS(BASE!$G:$G,BASE!$L:$L,$C14,BASE!$J:$J,$B14,BASE!$A:$A,J$6) -> 0 | K14: =SUMIFS(BASE!$G:$G,BASE!$L:$L,$C14,BASE!$J:$J,$B14,BASE!$A:$A,K$6) -> 0 | L14: =SUMIFS(BASE!$G:$G,BASE!$L:$L,$C14,BASE!$J:$J,$B14,BASE!$A:$A,L$6) -> 0 | M14: =SUMIFS(BASE!$G:$G,BASE!$L:$L,$C14,BASE!$J:$J,$B14,BASE!$A:$A,M$6) -> 0 | N14: =SUMIFS(BASE!$G:$G,BASE!$L:$L,$C14,BASE!$J:$J,$B14,BASE!$A:$A,N$6) -> 0 | ... R14: =SUMIFS(BASE!$G:$G,BASE!$L:$L,$C14,BASE!$J:$J,$B14,BASE!$A:$A,R$6) -> 0 | T14: =IF(AND(N14=0),"ZERADO","COM TROCAS") -> ZERADO
B15: ANA PAULA TARGINO TRINDADE | C15: NE | D15: =COUNTIFS(PDVS!H:H,"SIM",PDVS!C:C,B15) -> 0 | E15: =COUNTIFS(PDVS!C:C,B15,PDVS!I:I,"SIM") -> 1 | F15: =IF(AND(D15=0,E15>=1),"Sim",IF(D15>=1,"Não",IF(AND(D15=0,E15=0),"Sim",""))) -> Sim | G15: =SUMIFS(BASE!$G:$G,BASE!$L:$L,$C15,BASE!$J:$J,$B15,BASE!$A:$A,G$6) -> 0 | H15: =SUMIFS(BASE!$G:$G,BASE!$L:$L,$C15,BASE!$J:$J,$B15,BASE!$A:$A,H$6) -> 0 | I15: =SUMIFS(BASE!$G:$G,BASE!$L:$L,$C15,BASE!$J:$J,$B15,BASE!$A:$A,I$6) -> 0 | J15: =SUMIFS(BASE!$G:$G,BASE!$L:$L,$C15,BASE!$J:$J,$B15,BASE!$A:$A,J$6) -> 0 | K15: =SUMIFS(BASE!$G:$G,BASE!$L:$L,$C15,BASE!$J:$J,$B15,BASE!$A:$A,K$6) -> 0 | L15: =SUMIFS(BASE!$G:$G,BASE!$L:$L,$C15,BASE!$J:$J,$B15,BASE!$A:$A,L$6) -> 0 | M15: =SUMIFS(BASE!$G:$G,BASE!$L:$L,$C15,BASE!$J:$J,$B15,BASE!$A:$A,M$6) -> 0 | N15: =SUMIFS(BASE!$G:$G,BASE!$L:$L,$C15,BASE!$J:$J,$B15,BASE!$A:$A,N$6) -> 0 | ... R15: =SUMIFS(BASE!$G:$G,BASE!$L:$L,$C15,BASE!$J:$J,$B15,BASE!$A:$A,R$6) -> 0 | T15: =IF(AND(N15=0),"ZERADO","COM TROCAS") -> ZERADO
B16: ANTONIO LINDOMAR DE OLIVEIRA EPP | C16: CO | D16: =COUNTIFS(PDVS!H:H,"SIM",PDVS!C:C,B16) -> 0 | E16: =COUNTIFS(PDVS!C:C,B16,PDVS!I:I,"SIM") -> 1 | F16: =IF(AND(D16=0,E16>=1),"Sim",IF(D16>=1,"Não",IF(AND(D16=0,E16=0),"Sim",""))) -> Sim | G16: =SUMIFS(BASE!$G:$G,BASE!$L:$L,$C16,BASE!$J:$J,$B16,BASE!$A:$A,G$6) -> 0 | H16: =SUMIFS(BASE!$G:$G,BASE!$L:$L,$C16,BASE!$J:$J,$B16,BASE!$A:$A,H$6) -> 0 | I16: =SUMIFS(BASE!$G:$G,BASE!$L:$L,$C16,BASE!$J:$J,$B16,BASE!$A:$A,I$6) -> 0 | J16: =SUMIFS(BASE!$G:$G,BASE!$L:$L,$C16,BASE!$J:$J,$B16,BASE!$A:$A,J$6) -> 0 | K16: =SUMIFS(BASE!$G:$G,BASE!$L:$L,$C16,BASE!$J:$J,$B16,BASE!$A:$A,K$6) -> 0 | L16: =SUMIFS(BASE!$G:$G,BASE!$L:$L,$C16,BASE!$J:$J,$B16,BASE!$A:$A,L$6) -> 0 | M16: =SUMIFS(BASE!$G:$G,BASE!$L:$L,$C16,BASE!$J:$J,$B16,BASE!$A:$A,M$6) -> 0 | N16: =SUMIFS(BASE!$G:$G,BASE!$L:$L,$C16,BASE!$J:$J,$B16,BASE!$A:$A,N$6) -> 0 | ... R16: =SUMIFS(BASE!$G:$G,BASE!$L:$L,$C16,BASE!$J:$J,$B16,BASE!$A:$A,R$6) -> 0 | T16: =IF(AND(N16=0),"ZERADO","COM TROCAS") -> ZERADO
B17: ARES TELECOM LTDA | C17: CO | D17: =COUNTIFS(PDVS!H:H,"SIM",PDVS!C:C,B17) -> 0 | E17: =COUNTIFS(PDVS!C:C,B17,PDVS!I:I,"SIM") -> 0 | F17: =IF(AND(D17=0,E17>=1),"Sim",IF(D17>=1,"Não",IF(AND(D17=0,E17=0),"Sim",""))) -> Sim | G17: =SUMIFS(BASE!$G:$G,BASE!$L:$L,$C17,BASE!$J:$J,$B17,BASE!$A:$A,G$6) -> 0 | H17: =SUMIFS(BASE!$G:$G,BASE!$L:$L,$C17,BASE!$J:$J,$B17,BASE!$A:$A,H$6) -> 0 | I17: =SUMIFS(BASE!$G:$G,BASE!$L:$L,$C17,BASE!$J:$J,$B17,BASE!$A:$A,I$6) -> 0 | J17: =SUMIFS(BASE!$G:$G,BASE!$L:$L,$C17,BASE!$J:$J,$B17,BASE!$A:$A,J$6) -> 0 | K17: =SUMIFS(BASE!$G:$G,BASE!$L:$L,$C17,BASE!$J:$J,$B17,BASE!$A:$A,K$6) -> 0 | L17: =SUMIFS(BASE!$G:$G,BASE!$L:$L,$C17,BASE!$J:$J,$B17,BASE!$A:$A,L$6) -> 0 | M17: =SUMIFS(BASE!$G:$G,BASE!$L:$L,$C17,BASE!$J:$J,$B17,BASE!$A:$A,M$6) -> 0 | N17: =SUMIFS(BASE!$G:$G,BASE!$L:$L,$C17,BASE!$J:$J,$B17,BASE!$A:$A,N$6) -> 0 | ... R17: =SUMIFS(BASE!$G:$G,BASE!$L:$L,$C17,BASE!$J:$J,$B17,BASE!$A:$A,R$6) -> 0 | T17: =IF(AND(N17=0),"ZERADO","COM TROCAS") -> ZERADO
B18: ATENDE CELULAR LTDA - ME | C18: MG | D18: =COUNTIFS(PDVS!H:H,"SIM",PDVS!C:C,B18) -> 1 | E18: =COUNTIFS(PDVS!C:C,B18,PDVS!I:I,"SIM") -> 1 | F18: =IF(AND(D18=0,E18>=1),"Sim",IF(D18>=1,"Não",IF(AND(D18=0,E18=0),"Sim",""))) -> Não | G18: =SUMIFS(BASE!$G:$G,BASE!$L:$L,$C18,BASE!$J:$J,$B18,BASE!$A:$A,G$6) -> 0 | H18: =SUMIFS(BASE!$G:$G,BASE!$L:$L,$C18,BASE!$J:$J,$B18,BASE!$A:$A,H$6) -> 0 | I18: =SUMIFS(BASE!$G:$G,BASE!$L:$L,$C18,BASE!$J:$J,$B18,BASE!$A:$A,I$6) -> 0 | J18: =SUMIFS(BASE!$G:$G,BASE!$L:$L,$C18,BASE!$J:$J,$B18,BASE!$A:$A,J$6) -> 0 | K18: =SUMIFS(BASE!$G:$G,BASE!$L:$L,$C18,BASE!$J:$J,$B18,BASE!$A:$A,K$6) -> 0 | L18: =SUMIFS(BASE!$G:$G,BASE!$L:$L,$C18,BASE!$J:$J,$B18,BASE!$A:$A,L$6) -> 0 | M18: =SUMIFS(BASE!$G:$G,BASE!$L:$L,$C18,BASE!$J:$J,$B18,BASE!$A:$A,M$6) -> 0 | N18: =SUMIFS(BASE!$G:$G,BASE!$L:$L,$C18,BASE!$J:$J,$B18,BASE!$A:$A,N$6) -> 0 | ... R18: =SUMIFS(BASE!$G:$G,BASE!$L:$L,$C18,BASE!$J:$J,$B18,BASE!$A:$A,R$6) -> 0 | T18: =IF(AND(N18=0),"ZERADO","COM TROCAS") -> ZERADO
... B177: VIRACLARO | C177: SP2 | D177: =COUNTIFS(PDVS!H:H,"SIM",PDVS!C:C,B177) -> 0 | E177: =COUNTIFS(PDVS!C:C,B177,PDVS!I:I,"SIM") -> 1 | F177: =IF(AND(D177=0,E177>=1),"Sim",IF(D177>=1,"Não",IF(AND(D177=0,E177=0),"Sim",""))) -> Sim | G177: =SUMIFS(BASE!$G:$G,BASE!$L:$L,$C177,BASE!$J:$J,$B177,BASE!$A:$A,G$6) -> 2 | H177: =SUMIFS(BASE!$G:$G,BASE!$L:$L,$C177,BASE!$J:$J,$B177,BASE!$A:$A,H$6) -> 0 | I177: =SUMIFS(BASE!$G:$G,BASE!$L:$L,$C177,BASE!$J:$J,$B177,BASE!$A:$A,I$6) -> 3 | J177: =SUMIFS(BASE!$G:$G,BASE!$L:$L,$C177,BASE!$J:$J,$B177,BASE!$A:$A,J$6) -> 1 | K177: =SUMIFS(BASE!$G:$G,BASE!$L:$L,$C177,BASE!$J:$J,$B177,BASE!$A:$A,K$6) -> 1 | L177: =SUMIFS(BASE!$G:$G,BASE!$L:$L,$C177,BASE!$J:$J,$B177,BASE!$A:$A,L$6) -> 2 | M177: =SUMIFS(BASE!$G:$G,BASE!$L:$L,$C177,BASE!$J:$J,$B177,BASE!$A:$A,M$6) -> 2 | N177: =SUMIFS(BASE!$G:$G,BASE!$L:$L,$C177,BASE!$J:$J,$B177,BASE!$A:$A,N$6) -> 6 | ... R177: =SUMIFS(BASE!$G:$G,BASE!$L:$L,$C177,BASE!$J:$J,$B177,BASE!$A:$A,R$6) -> 0 | T177: =IF(AND(N177=0),"ZERADO","COM TROCAS") -> COM TROCAS
G178: =SUM(G7:G177) -> 1992 | H178: =SUM(H7:H177) -> 1651 | I178: =SUM(I7:I177) -> 2955 | J178: =SUM(J7:J177) -> 2357 | K178: =SUM(K7:K177) -> 2919 | L178: =SUM(L7:L177) -> 3004 | M178: =SUM(M7:M177) -> 5021 | N178: =SUM(N7:N177) -> 3842 | ... R178: =SUM(R7:R177) -> 0

Sheet PDVS
B2: CÓD | C2: GRUPO | D2: GN | E2: GF | F2: CIDADE | G2: REG | H2: REPASSE? | I2: TEM BOOST? | J2: ELEGÍVEL? | K2: 46023 | L2: 46054 | M2: 46082 | N2: 46113 | O2: 46143 | P2: 46174 | Q2: 46204 | R2: 46235 | S2: 46266 | T2: 46296 | U2: 46327 | V2: 46357 | X2: STATUS
B3: 14HB | C3: FABIANA GONCALVES DA SILVA LINS E CIA LTDA | D3: ADILSON MARQUES DA SILVA | E3: LUIZ DE SOUSA LEAL NETO | F3: GARANHUNS | G3: NE | H3: =IFERROR(IF(_xlfn.XLOOKUP(B3,REPASSE!D:D,REPASSE!D:D)="","Não","Sim"),"Não") -> Não | I3: =IF(_xlfn.XLOOKUP(B3,'BOOST LIBERADO'!B:B,'BOOST LIBERADO'!B:B,"Não")="Não","Não","Sim") -> Sim | J3: =IF(AND(H3="Não",I3="Sim"),"Sim","Não") -> Sim | K3: =SUMIFS(BASE!$G:$G,BASE!$B:$B,$B3,BASE!$L:$L,$G3,BASE!$J:$J,$C3,BASE!$A:$A,K$2) -> 0 | L3: =SUMIFS(BASE!$G:$G,BASE!$B:$B,$B3,BASE!$L:$L,$G3,BASE!$J:$J,$C3,BASE!$A:$A,L$2) -> 0 | M3: =SUMIFS(BASE!$G:$G,BASE!$B:$B,$B3,BASE!$L:$L,$G3,BASE!$J:$J,$C3,BASE!$A:$A,M$2) -> 0 | N3: =SUMIFS(BASE!$G:$G,BASE!$B:$B,$B3,BASE!$L:$L,$G3,BASE!$J:$J,$C3,BASE!$A:$A,N$2) -> 0 | O3: =SUMIFS(BASE!$G:$G,BASE!$B:$B,$B3,BASE!$L:$L,$G3,BASE!$J:$J,$C3,BASE!$A:$A,O$2) -> 0 | P3: =SUMIFS(BASE!$G:$G,BASE!$B:$B,$B3,BASE!$L:$L,$G3,BASE!$J:$J,$C3,BASE!$A:$A,P$2) -> 0 | Q3: =SUMIFS(BASE!$G:$G,BASE!$B:$B,$B3,BASE!$L:$L,$G3,BASE!$J:$J,$C3,BASE!$A:$A,Q$2) -> 0 | R3: =SUMIFS(BASE!$G:$G,BASE!$B:$B,$B3,BASE!$L:$L,$G3,BASE!$J:$J,$C3,BASE!$A:$A,R$2) -> 0 | ... V3: =SUMIFS(BASE!$G:$G,BASE!$B:$B,$B3,BASE!$L:$L,$G3,BASE!$J:$J,$C3,BASE!$A:$A,V$2) -> 0 | X3: =IF(AND(R3=0),"ZERADO","COM TROCAS") -> ZERADO
B4: 4KDV | C4: CARLOS FREDERICO E FILHOS COMERCIO | D4: HELOISA IONE OLIVEIRA DE ARAUJO | E4: FLAVIO GOMES RODRIGUES DOS SANTOS | F4: JOAO PESSOA | G4: NE | H4: =IFERROR(IF(_xlfn.XLOOKUP(B4,REPASSE!D:D,REPASSE!D:D)="","Não","Sim"),"Não") -> Não | I4: =IF(_xlfn.XLOOKUP(B4,'BOOST LIBERADO'!B:B,'BOOST LIBERADO'!B:B,"Não")="Não","Não","Sim") -> Sim | J4: =IF(AND(H4="Não",I4="Sim"),"Sim","Não") -> Sim | K4: =SUMIFS(BASE!$G:$G,BASE!$B:$B,$B4,BASE!$L:$L,$G4,BASE!$J:$J,$C4,BASE!$A:$A,K$2) -> 0 | L4: =SUMIFS(BASE!$G:$G,BASE!$B:$B,$B4,BASE!$L:$L,$G4,BASE!$J:$J,$C4,BASE!$A:$A,L$2) -> 0 | M4: =SUMIFS(BASE!$G:$G,BASE!$B:$B,$B4,BASE!$L:$L,$G4,BASE!$J:$J,$C4,BASE!$A:$A,M$2) -> 0 | N4: =SUMIFS(BASE!$G:$G,BASE!$B:$B,$B4,BASE!$L:$L,$G4,BASE!$J:$J,$C4,BASE!$A:$A,N$2) -> 0 | O4: =SUMIFS(BASE!$G:$G,BASE!$B:$B,$B4,BASE!$L:$L,$G4,BASE!$J:$J,$C4,BASE!$A:$A,O$2) -> 0 | P4: =SUMIFS(BASE!$G:$G,BASE!$B:$B,$B4,BASE!$L:$L,$G4,BASE!$J:$J,$C4,BASE!$A:$A,P$2) -> 0 | Q4: =SUMIFS(BASE!$G:$G,BASE!$B:$B,$B4,BASE!$L:$L,$G4,BASE!$J:$J,$C4,BASE!$A:$A,Q$2) -> 0 | R4: =SUMIFS(BASE!$G:$G,BASE!$B:$B,$B4,BASE!$L:$L,$G4,BASE!$J:$J,$C4,BASE!$A:$A,R$2) -> 0 | ... V4: =SUMIFS(BASE!$G:$G,BASE!$B:$B,$B4,BASE!$L:$L,$G4,BASE!$J:$J,$C4,BASE!$A:$A,V$2) -> 0 | X4: =IF(AND(R4=0),"ZERADO","COM TROCAS") -> ZERADO
B5: 5LYK | C5: HARCOS COMERCIO E SERVICOS LTDA - EPP | D5: ISADORA NASCIMENTO SILVA | E5: ADNO KEVERSON DOS SANTOS CASTRO | F5: NATAL | G5: NE | H5: =IFERROR(IF(_xlfn.XLOOKUP(B5,REPASSE!D:D,REPASSE!D:D)="","Não","Sim"),"Não") -> Não | I5: =IF(_xlfn.XLOOKUP(B5,'BOOST LIBERADO'!B:B,'BOOST LIBERADO'!B:B,"Não")="Não","Não","Sim") -> Sim | J5: =IF(AND(H5="Não",I5="Sim"),"Sim","Não") -> Sim | K5: =SUMIFS(BASE!$G:$G,BASE!$B:$B,$B5,BASE!$L:$L,$G5,BASE!$J:$J,$C5,BASE!$A:$A,K$2) -> 28 | L5: =SUMIFS(BASE!$G:$G,BASE!$B:$B,$B5,BASE!$L:$L,$G5,BASE!$J:$J,$C5,BASE!$A:$A,L$2) -> 20 | M5: =SUMIFS(BASE!$G:$G,BASE!$B:$B,$B5,BASE!$L:$L,$G5,BASE!$J:$J,$C5,BASE!$A:$A,M$2) -> 9 | N5: =SUMIFS(BASE!$G:$G,BASE!$B:$B,$B5,BASE!$L:$L,$G5,BASE!$J:$J,$C5,BASE!$A:$A,N$2) -> 7 | O5: =SUMIFS(BASE!$G:$G,BASE!$B:$B,$B5,BASE!$L:$L,$G5,BASE!$J:$J,$C5,BASE!$A:$A,O$2) -> 8 | P5: =SUMIFS(BASE!$G:$G,BASE!$B:$B,$B5,BASE!$L:$L,$G5,BASE!$J:$J,$C5,BASE!$A:$A,P$2) -> 16 | Q5: =SUMIFS(BASE!$G:$G,BASE!$B:$B,$B5,BASE!$L:$L,$G5,BASE!$J:$J,$C5,BASE!$A:$A,Q$2) -> 29 | R5: =SUMIFS(BASE!$G:$G,BASE!$B:$B,$B5,BASE!$L:$L,$G5,BASE!$J:$J,$C5,BASE!$A:$A,R$2) -> 19 | ... V5: =SUMIFS(BASE!$G:$G,BASE!$B:$B,$B5,BASE!$L:$L,$G5,BASE!$J:$J,$C5,BASE!$A:$A,V$2) -> 0 | X5: =IF(AND(R5=0),"ZERADO","COM TROCAS") -> COM TROCAS
B6: 5QC8 | C6: HARCOS COMERCIO E SERVICOS LTDA - EPP | D6: MICHELLE SALUSTRE MARCATO | E6: FABRICIO SILVA DE ARAUJO | F6: MACEIO | G6: NE | H6: =IFERROR(IF(_xlfn.XLOOKUP(B6,REPASSE!D:D,REPASSE!D:D)="","Não","Sim"),"Não") -> Não | I6: =IF(_xlfn.XLOOKUP(B6,'BOOST LIBERADO'!B:B,'BOOST LIBERADO'!B:B,"Não")="Não","Não","Sim") -> Sim | J6: =IF(AND(H6="Não",I6="Sim"),"Sim","Não") -> Sim | K6: =SUMIFS(BASE!$G:$G,BASE!$B:$B,$B6,BASE!$L:$L,$G6,BASE!$J:$J,$C6,BASE!$A:$A,K$2) -> 8 | L6: =SUMIFS(BASE!$G:$G,BASE!$B:$B,$B6,BASE!$L:$L,$G6,BASE!$J:$J,$C6,BASE!$A:$A,L$2) -> 11 | M6: =SUMIFS(BASE!$G:$G,BASE!$B:$B,$B6,BASE!$L:$L,$G6,BASE!$J:$J,$C6,BASE!$A:$A,M$2) -> 17 | N6: =SUMIFS(BASE!$G:$G,BASE!$B:$B,$B6,BASE!$L:$L,$G6,BASE!$J:$J,$C6,BASE!$A:$A,N$2) -> 10 | O6: =SUMIFS(BASE!$G:$G,BASE!$B:$B,$B6,BASE!$L:$L,$G6,BASE!$J:$J,$C6,BASE!$A:$A,O$2) -> 15 | P6: =SUMIFS(BASE!$G:$G,BASE!$B:$B,$B6,BASE!$L:$L,$G6,BASE!$J:$J,$C6,BASE!$A:$A,P$2) -> 11 | Q6: =SUMIFS(BASE!$G:$G,BASE!$B:$B,$B6,BASE!$L:$L,$G6,BASE!$J:$J,$C6,BASE!$A:$A,Q$2) -> 20 | R6: =SUMIFS(BASE!$G:$G,BASE!$B:$B,$B6,BASE!$L:$L,$G6,BASE!$J:$J,$C6,BASE!$A:$A,R$2) -> 3 | ... V6: =SUMIFS(BASE!$G:$G,BASE!$B:$B,$B6,BASE!$L:$L,$G6,BASE!$J:$J,$C6,BASE!$A:$A,V$2) -> 0 | X6: =IF(AND(R6=0),"ZERADO","COM TROCAS") -> COM TROCAS
B7: B1RJ | C7: SELF COMERCIO E SERVICOS EM TELEFON | D7: FRANCISCA ALINE ALVES BENTO | E7: DIEGO HENRIQUE FERREIRA DANTAS | F7: FORTALEZA | G7: NE | H7: =IFERROR(IF(_xlfn.XLOOKUP(B7,REPASSE!D:D,REPASSE!D:D)="","Não","Sim"),"Não") -> Não | I7: =IF(_xlfn.XLOOKUP(B7,'BOOST LIBERADO'!B:B,'BOOST LIBERADO'!B:B,"Não")="Não","Não","Sim") -> Não | J7: =IF(AND(H7="Não",I7="Sim"),"Sim","Não") -> Não | K7: =SUMIFS(BASE!$G:$G,BASE!$B:$B,$B7,BASE!$L:$L,$G7,BASE!$J:$J,$C7,BASE!$A:$A,K$2) -> 0 | L7: =SUMIFS(BASE!$G:$G,BASE!$B:$B,$B7,BASE!$L:$L,$G7,BASE!$J:$J,$C7,BASE!$A:$A,L$2) -> 0 | M7: =SUMIFS(BASE!$G:$G,BASE!$B:$B,$B7,BASE!$L:$L,$G7,BASE!$J:$J,$C7,BASE!$A:$A,M$2) -> 0 | N7: =SUMIFS(BASE!$G:$G,BASE!$B:$B,$B7,BASE!$L:$L,$G7,BASE!$J:$J,$C7,BASE!$A:$A,N$2) -> 0 | O7: =SUMIFS(BASE!$G:$G,BASE!$B:$B,$B7,BASE!$L:$L,$G7,BASE!$J:$J,$C7,BASE!$A:$A,O$2) -> 0 | P7: =SUMIFS(BASE!$G:$G,BASE!$B:$B,$B7,BASE!$L:$L,$G7,BASE!$J:$J,$C7,BASE!$A:$A,P$2) -> 0 | Q7: =SUMIFS(BASE!$G:$G,BASE!$B:$B,$B7,BASE!$L:$L,$G7,BASE!$J:$J,$C7,BASE!$A:$A,Q$2) -> 0 | R7: =SUMIFS(BASE!$G:$G,BASE!$B:$B,$B7,BASE!$L:$L,$G7,BASE!$J:$J,$C7,BASE!$A:$A,R$2) -> 0 | ... V7: =SUMIFS(BASE!$G:$G,BASE!$B:$B,$B7,BASE!$L:$L,$G7,BASE!$J:$J,$C7,BASE!$A:$A,V$2) -> 0 | X7: =IF(AND(R7=0),"ZERADO","COM TROCAS") -> ZERADO
B8: DP0N | C8: SELF COMERCIO E SERVICOS EM TELEFON | D8: FRANCISCA ALINE ALVES BENTO | E8: DIEGO HENRIQUE FERREIRA DANTAS | F8: FORTALEZA | G8: NE | H8: =IFERROR(IF(_xlfn.XLOOKUP(B8,REPASSE!D:D,REPASSE!D:D)="","Não","Sim"),"Não") -> Não | I8: =IF(_xlfn.XLOOKUP(B8,'BOOST LIBERADO'!B:B,'BOOST LIBERADO'!B:B,"Não")="Não","Não","Sim") -> Não | J8: =IF(AND(H8="Não",I8="Sim"),"Sim","Não") -> Não | K8: =SUMIFS(BASE!$G:$G,BASE!$B:$B,$B8,BASE!$L:$L,$G8,BASE!$J:$J,$C8,BASE!$A:$A,K$2) -> 0 | L8: =SUMIFS(BASE!$G:$G,BASE!$B:$B,$B8,BASE!$L:$L,$G8,BASE!$J:$J,$C8,BASE!$A:$A,L$2) -> 0 | M8: =SUMIFS(BASE!$G:$G,BASE!$B:$B,$B8,BASE!$L:$L,$G8,BASE!$J:$J,$C8,BASE!$A:$A,M$2) -> 0 | N8: =SUMIFS(BASE!$G:$G,BASE!$B:$B,$B8,BASE!$L:$L,$G8,BASE!$J:$J,$C8,BASE!$A:$A,N$2) -> 0 | O8: =SUMIFS(BASE!$G:$G,BASE!$B:$B,$B8,BASE!$L:$L,$G8,BASE!$J:$J,$C8,BASE!$A:$A,O$2) -> 0 | P8: =SUMIFS(BASE!$G:$G,BASE!$B:$B,$B8,BASE!$L:$L,$G8,BASE!$J:$J,$C8,BASE!$A:$A,P$2) -> 0 | Q8: =SUMIFS(BASE!$G:$G,BASE!$B:$B,$B8,BASE!$L:$L,$G8,BASE!$J:$J,$C8,BASE!$A:$A,Q$2) -> 0 | R8: =SUMIFS(BASE!$G:$G,BASE!$B:$B,$B8,BASE!$L:$L,$G8,BASE!$J:$J,$C8,BASE!$A:$A,R$2) -> 0 | ... V8: =SUMIFS(BASE!$G:$G,BASE!$B:$B,$B8,BASE!$L:$L,$G8,BASE!$J:$J,$C8,BASE!$A:$A,V$2) -> 0 | X8: =IF(AND(R8=0),"ZERADO","COM TROCAS") -> ZERADO
B9: FCZ6 | C9: CARLOS FREDERICO E FILHOS COMERCIO | D9: IRANILDE VERISSIMO DE MEDEIROS | E9: FLAVIO GOMES RODRIGUES DOS SANTOS | F9: JOAO PESSOA | G9: NE | H9: =IFERROR(IF(_xlfn.XLOOKUP(B9,REPASSE!D:D,REPASSE!D:D)="","Não","Sim"),"Não") -> Não | I9: =IF(_xlfn.XLOOKUP(B9,'BOOST LIBERADO'!B:B,'BOOST LIBERADO'!B:B,"Não")="Não","Não","Sim") -> Sim | J9: =IF(AND(H9="Não",I9="Sim"),"Sim","Não") -> Sim | K9: =SUMIFS(BASE!$G:$G,BASE!$B:$B,$B9,BASE!$L:$L,$G9,BASE!$J:$J,$C9,BASE!$A:$A,K$2) -> 0 | L9: =SUMIFS(BASE!$G:$G,BASE!$B:$B,$B9,BASE!$L:$L,$G9,BASE!$J:$J,$C9,BASE!$A:$A,L$2) -> 0 | M9: =SUMIFS(BASE!$G:$G,BASE!$B:$B,$B9,BASE!$L:$L,$G9,BASE!$J:$J,$C9,BASE!$A:$A,M$2) -> 0 | N9: =SUMIFS(BASE!$G:$G,BASE!$B:$B,$B9,BASE!$L:$L,$G9,BASE!$J:$J,$C9,BASE!$A:$A,N$2) -> 0 | O9: =SUMIFS(BASE!$G:$G,BASE!$B:$B,$B9,BASE!$L:$L,$G9,BASE!$J:$J,$C9,BASE!$A:$A,O$2) -> 0 | P9: =SUMIFS(BASE!$G:$G,BASE!$B:$B,$B9,BASE!$L:$L,$G9,BASE!$J:$J,$C9,BASE!$A:$A,P$2) -> 0 | Q9: =SUMIFS(BASE!$G:$G,BASE!$B:$B,$B9,BASE!$L:$L,$G9,BASE!$J:$J,$C9,BASE!$A:$A,Q$2) -> 0 | R9: =SUMIFS(BASE!$G:$G,BASE!$B:$B,$B9,BASE!$L:$L,$G9,BASE!$J:$J,$C9,BASE!$A:$A,R$2) -> 0 | ... V9: =SUMIFS(BASE!$G:$G,BASE!$B:$B,$B9,BASE!$L:$L,$G9,BASE!$J:$J,$C9,BASE!$A:$A,V$2) -> 0 | X9: =IF(AND(R9=0),"ZERADO","COM TROCAS") -> ZERADO
B10: GR53 | C10: DELTA CELL TELECOMUNICACOES LTDA | D10: ALIENNY BARBOSA MACEDO | E10: DAVID OLIVEIRA DA COSTA | F10: PIRIPIRI | G10: NE | H10: =IFERROR(IF(_xlfn.XLOOKUP(B10,REPASSE!D:D,REPASSE!D:D)="","Não","Sim"),"Não") -> Não | I10: =IF(_xlfn.XLOOKUP(B10,'BOOST LIBERADO'!B:B,'BOOST LIBERADO'!B:B,"Não")="Não","Não","Sim") -> Sim | J10: =IF(AND(H10="Não",I10="Sim"),"Sim","Não") -> Sim | K10: =SUMIFS(BASE!$G:$G,BASE!$B:$B,$B10,BASE!$L:$L,$G10,BASE!$J:$J,$C10,BASE!$A:$A,K$2) -> 0 | L10: =SUMIFS(BASE!$G:$G,BASE!$B:$B,$B10,BASE!$L:$L,$G10,BASE!$J:$J,$C10,BASE!$A:$A,L$2) -> 0 | M10: =SUMIFS(BASE!$G:$G,BASE!$B:$B,$B10,BASE!$L:$L,$G10,BASE!$J:$J,$C10,BASE!$A:$A,M$2) -> 0 | N10: =SUMIFS(BASE!$G:$G,BASE!$B:$B,$B10,BASE!$L:$L,$G10,BASE!$J:$J,$C10,BASE!$A:$A,N$2) -> 0 | O10: =SUMIFS(BASE!$G:$G,BASE!$B:$B,$B10,BASE!$L:$L,$G10,BASE!$J:$J,$C10,BASE!$A:$A,O$2) -> 0 | P10: =SUMIFS(BASE!$G:$G,BASE!$B:$B,$B10,BASE!$L:$L,$G10,BASE!$J:$J,$C10,BASE!$A:$A,P$2) -> 0 | Q10: =SUMIFS(BASE!$G:$G,BASE!$B:$B,$B10,BASE!$L:$L,$G10,BASE!$J:$J,$C10,BASE!$A:$A,Q$2) -> 0 | R10: =SUMIFS(BASE!$G:$G,BASE!$B:$B,$B10,BASE!$L:$L,$G10,BASE!$J:$J,$C10,BASE!$A:$A,R$2) -> 0 | ... V10: =SUMIFS(BASE!$G:$G,BASE!$B:$B,$B10,BASE!$L:$L,$G10,BASE!$J:$J,$C10,BASE!$A:$A,V$2) -> 0 | X10: =IF(AND(R10=0),"ZERADO","COM TROCAS") -> ZERADO
B11: H0ZF | C11: R & R HIPER COMERCIO LTDA | D11: DENISE CIBELLY FERNANDES BATALHA | E11: ADNO KEVERSON DOS SANTOS CASTRO | F11: NATAL | G11: NE | H11: =IFERROR(IF(_xlfn.XLOOKUP(B11,REPASSE!D:D,REPASSE!D:D)="","Não","Sim"),"Não") -> Não | I11: =IF(_xlfn.XLOOKUP(B11,'BOOST LIBERADO'!B:B,'BOOST LIBERADO'!B:B,"Não")="Não","Não","Sim") -> Sim | J11: =IF(AND(H11="Não",I11="Sim"),"Sim","Não") -> Sim | K11: =SUMIFS(BASE!$G:$G,BASE!$B:$B,$B11,BASE!$L:$L,$G11,BASE!$J:$J,$C11,BASE!$A:$A,K$2) -> 3 | L11: =SUMIFS(BASE!$G:$G,BASE!$B:$B,$B11,BASE!$L:$L,$G11,BASE!$J:$J,$C11,BASE!$A:$A,L$2) -> 2 | M11: =SUMIFS(BASE!$G:$G,BASE!$B:$B,$B11,BASE!$L:$L,$G11,BASE!$J:$J,$C11,BASE!$A:$A,M$2) -> 0 | N11: =SUMIFS(BASE!$G:$G,BASE!$B:$B,$B11,BASE!$L:$L,$G11,BASE!$J:$J,$C11,BASE!$A:$A,N$2) -> 3 | O11: =SUMIFS(BASE!$G:$G,BASE!$B:$B,$B11,BASE!$L:$L,$G11,BASE!$J:$J,$C11,BASE!$A:$A,O$2) -> 8 | P11: =SUMIFS(BASE!$G:$G,BASE!$B:$B,$B11,BASE!$L:$L,$G11,BASE!$J:$J,$C11,BASE!$A:$A,P$2) -> 3 | Q11: =SUMIFS(BASE!$G:$G,BASE!$B:$B,$B11,BASE!$L:$L,$G11,BASE!$J:$J,$C11,BASE!$A:$A,Q$2) -> 16 | R11: =SUMIFS(BASE!$G:$G,BASE!$B:$B,$B11,BASE!$L:$L,$G11,BASE!$J:$J,$C11,BASE!$A:$A,R$2) -> 15 | ... V11: =SUMIFS(BASE!$G:$G,BASE!$B:$B,$B11,BASE!$L:$L,$G11,BASE!$J:$J,$C11,BASE!$A:$A,V$2) -> 0 | X11: =IF(AND(R11=0),"ZERADO","COM TROCAS") -> COM TROCAS
B12: IE2M | C12: HARCOS COMERCIO E SERVICOS LTDA - EPP | D12: MICHELLE SALUSTRE MARCATO | E12: FABRICIO SILVA DE ARAUJO | F12: MACEIO | G12: NE | H12: =IFERROR(IF(_xlfn.XLOOKUP(B12,REPASSE!D:D,REPASSE!D:D)="","Não","Sim"),"Não") -> Não | I12: =IF(_xlfn.XLOOKUP(B12,'BOOST LIBERADO'!B:B,'BOOST LIBERADO'!B:B,"Não")="Não","Não","Sim") -> Sim | J12: =IF(AND(H12="Não",I12="Sim"),"Sim","Não") -> Sim | K12: =SUMIFS(BASE!$G:$G,BASE!$B:$B,$B12,BASE!$L:$L,$G12,BASE!$J:$J,$C12,BASE!$A:$A,K$2) -> 20 | L12: =SUMIFS(BASE!$G:$G,BASE!$B:$B,$B12,BASE!$L:$L,$G12,BASE!$J:$J,$C12,BASE!$A:$A,L$2) -> 5 | M12: =SUMIFS(BASE!$G:$G,BASE!$B:$B,$B12,BASE!$L:$L,$G12,BASE!$J:$J,$C12,BASE!$A:$A,M$2) -> 22 | N12: =SUMIFS(BASE!$G:$G,BASE!$B:$B,$B12,BASE!$L:$L,$G12,BASE!$J:$J,$C12,BASE!$A:$A,N$2) -> 14 | O12: =SUMIFS(BASE!$G:$G,BASE!$B:$B,$B12,BASE!$L:$L,$G12,BASE!$J:$J,$C12,BASE!$A:$A,O$2) -> 10 | P12: =SUMIFS(BASE!$G:$G,BASE!$B:$B,$B12,BASE!$L:$L,$G12,BASE!$J:$J,$C12,BASE!$A:$A,P$2) -> 20 | Q12: =SUMIFS(BASE!$G:$G,BASE!$B:$B,$B12,BASE!$L:$L,$G12,BASE!$J:$J,$C12,BASE!$A:$A,Q$2) -> 23 | R12: =SUMIFS(BASE!$G:$G,BASE!$B:$B,$B12,BASE!$L:$L,$G12,BASE!$J:$J,$C12,BASE!$A:$A,R$2) -> 27 | ... V12: =SUMIFS(BASE!$G:$G,BASE!$B:$B,$B12,BASE!$L:$L,$G12,BASE!$J:$J,$C12,BASE!$A:$A,V$2) -> 0 | X12: =IF(AND(R12=0),"ZERADO","COM TROCAS") -> COM TROCAS
B13: IKFK | C13: HARCOS COMERCIO E SERVICOS LTDA - EPP | D13: MICHELLE SALUSTRE MARCATO | E13: FABRICIO SILVA DE ARAUJO | F13: MACEIO | G13: NE | H13: =IFERROR(IF(_xlfn.XLOOKUP(B13,REPASSE!D:D,REPASSE!D:D)="","Não","Sim"),"Não") -> Não | I13: =IF(_xlfn.XLOOKUP(B13,'BOOST LIBERADO'!B:B,'BOOST LIBERADO'!B:B,"Não")="Não","Não","Sim") -> Sim | J13: =IF(AND(H13="Não",I13="Sim"),"Sim","Não") -> Sim | K13: =SUMIFS(BASE!$G:$G,BASE!$B:$B,$B13,BASE!$L:$L,$G13,BASE!$J:$J,$C13,BASE!$A:$A,K$2) -> 10 | L13: =SUMIFS(BASE!$G:$G,BASE!$B:$B,$B13,BASE!$L:$L,$G13,BASE!$J:$J,$C13,BASE!$A:$A,L$2) -> 6 | M13: =SUMIFS(BASE!$G:$G,BASE!$B:$B,$B13,BASE!$L:$L,$G13,BASE!$J:$J,$C13,BASE!$A:$A,M$2) -> 10 | N13: =SUMIFS(BASE!$G:$G,BASE!$B:$B,$B13,BASE!$L:$L,$G13,BASE!$J:$J,$C13,BASE!$A:$A,N$2) -> 12 | O13: =SUMIFS(BASE!$G:$G,BASE!$B:$B,$B13,BASE!$L:$L,$G13,BASE!$J:$J,$C13,BASE!$A:$A,O$2) -> 9 | P13: =SUMIFS(BASE!$G:$G,BASE!$B:$B,$B13,BASE!$L:$L,$G13,BASE!$J:$J,$C13,BASE!$A:$A,P$2) -> 10 | Q13: =SUMIFS(BASE!$G:$G,BASE!$B:$B,$B13,BASE!$L:$L,$G13,BASE!$J:$J,$C13,BASE!$A:$A,Q$2) -> 20 | R13: =SUMIFS(BASE!$G:$G,BASE!$B:$B,$B13,BASE!$L:$L,$G13,BASE!$J:$J,$C13,BASE!$A:$A,R$2) -> 26 | ... V13: =SUMIFS(BASE!$G:$G,BASE!$B:$B,$B13,BASE!$L:$L,$G13,BASE!$J:$J,$C13,BASE!$A:$A,V$2) -> 0 | X13: =IF(AND(R13=0),"ZERADO","COM TROCAS") -> COM TROCAS
B14: LPK0 | C14: SANTOS E TENORIO TELECOM LTDA | D14: JULYANE CAVALCANTE GOMES DA SILVA | E14: FABRICIO SILVA DE ARAUJO | F14: PENEDO | G14: NE | H14: =IFERROR(IF(_xlfn.XLOOKUP(B14,REPASSE!D:D,REPASSE!D:D)="","Não","Sim"),"Não") -> Não | I14: =IF(_xlfn.XLOOKUP(B14,'BOOST LIBERADO'!B:B,'BOOST LIBERADO'!B:B,"Não")="Não","Não","Sim") -> Sim | J14: =IF(AND(H14="Não",I14="Sim"),"Sim","Não") -> Sim | K14: =SUMIFS(BASE!$G:$G,BASE!$B:$B,$B14,BASE!$L:$L,$G14,BASE!$J:$J,$C14,BASE!$A:$A,K$2) -> 0 | L14: =SUMIFS(BASE!$G:$G,BASE!$B:$B,$B14,BASE!$L:$L,$G14,BASE!$J:$J,$C14,BASE!$A:$A,L$2) -> 0 | M14: =SUMIFS(BASE!$G:$G,BASE!$B:$B,$B14,BASE!$L:$L,$G14,BASE!$J:$J,$C14,BASE!$A:$A,M$2) -> 0 | N14: =SUMIFS(BASE!$G:$G,BASE!$B:$B,$B14,BASE!$L:$L,$G14,BASE!$J:$J,$C14,BASE!$A:$A,N$2) -> 0 | O14: =SUMIFS(BASE!$G:$G,BASE!$B:$B,$B14,BASE!$L:$L,$G14,BASE!$J:$J,$C14,BASE!$A:$A,O$2) -> 0 | P14: =SUMIFS(BASE!$G:$G,BASE!$B:$B,$B14,BASE!$L:$L,$G14,BASE!$J:$J,$C14,BASE!$A:$A,P$2) -> 0 | Q14: =SUMIFS(BASE!$G:$G,BASE!$B:$B,$B14,BASE!$L:$L,$G14,BASE!$J:$J,$C14,BASE!$A:$A,Q$2) -> 0 | R14: =SUMIFS(BASE!$G:$G,BASE!$B:$B,$B14,BASE!$L:$L,$G14,BASE!$J:$J,$C14,BASE!$A:$A,R$2) -> 0 | ... V14: =SUMIFS(BASE!$G:$G,BASE!$B:$B,$B14,BASE!$L:$L,$G14,BASE!$J:$J,$C14,BASE!$A:$A,V$2) -> 0 | X14: =IF(AND(R14=0),"ZERADO","COM TROCAS") -> ZERADO
... B180: X8IF | C180: CENTERCELL TELECOMUNICACOES CARANGO | D180: JOSIANA EMILIA SILVA FARIA | E180: KAROLINE LAMAS DE ANDRADE | F180: ESPERA FELIZ | G180: MG | H180: =IFERROR(IF(_xlfn.XLOOKUP(B180,REPASSE!D:D,REPASSE!D:D)="","Não","Sim"),"Não") -> Não | I180: =IF(_xlfn.XLOOKUP(B180,'BOOST LIBERADO'!B:B,'BOOST LIBERADO'!B:B,"Não")="Não","Não","Sim") -> Sim | J180: =IF(AND(H180="Não",I180="Sim"),"Sim","Não") -> Sim | K180: =SUMIFS(BASE!$G:$G,BASE!$B:$B,$B180,BASE!$L:$L,$G180,BASE!$J:$J,$C180,BASE!$A:$A,K$2) -> 0 | L180: =SUMIFS(BASE!$G:$G,BASE!$B:$B,$B180,BASE!$L:$L,$G180,BASE!$J:$J,$C180,BASE!$A:$A,L$2) -> 0 | M180: =SUMIFS(BASE!$G:$G,BASE!$B:$B,$B180,BASE!$L:$L,$G180,BASE!$J:$J,$C180,BASE!$A:$A,M$2) -> 0 | N180: =SUMIFS(BASE!$G:$G,BASE!$B:$B,$B180,BASE!$L:$L,$G180,BASE!$J:$J,$C180,BASE!$A:$A,N$2) -> 0 | O180: =SUMIFS(BASE!$G:$G,BASE!$B:$B,$B180,BASE!$L:$L,$G180,BASE!$J:$J,$C180,BASE!$A:$A,O$2) -> 0 | P180: =SUMIFS(BASE!$G:$G,BASE!$B:$B,$B180,BASE!$L:$L,$G180,BASE!$J:$J,$C180,BASE!$A:$A,P$2) -> 0 | Q180: =SUMIFS(BASE!$G:$G,BASE!$B:$B,$B180,BASE!$L:$L,$G180,BASE!$J:$J,$C180,BASE!$A:$A,Q$2) -> 0 | R180: =SUMIFS(BASE!$G:$G,BASE!$B:$B,$B180,BASE!$L:$L,$G180,BASE!$J:$J,$C180,BASE!$A:$A,R$2) -> 0 | ... V180: =SUMIFS(BASE!$G:$G,BASE!$B:$B,$B180,BASE!$L:$L,$G180,BASE!$J:$J,$C180,BASE!$A:$A,V$2) -> 0 | X180: =IF(AND(R180=0),"ZERADO","COM TROCAS") -> ZERADO
B181: 4540 | C181: CELLULAR.COM | D181: LIZANDRA PERES DA SILVA | E181: JORGE PEREIRA AZAMBUJA FILHO | F181: VESPASIANO | G181: MG | H181: =IFERROR(IF(_xlfn.XLOOKUP(B181,REPASSE!D:D,REPASSE!D:D)="","Não","Sim"),"Não") -> Não | I181: =IF(_xlfn.XLOOKUP(B181,'BOOST LIBERADO'!B:B,'BOOST LIBERADO'!B:B,"Não")="Não","Não","Sim") -> Não | J181: =IF(AND(H181="Não",I181="Sim"),"Sim","Não") -> Não | K181: =SUMIFS(BASE!$G:$G,BASE!$B:$B,$B181,BASE!$L:$L,$G181,BASE!$J:$J,$C181,BASE!$A:$A,K$2) -> 0 | L181: =SUMIFS(BASE!$G:$G,BASE!$B:$B,$B181,BASE!$L:$L,$G181,BASE!$J:$J,$C181,BASE!$A:$A,L$2) -> 0 | M181: =SUMIFS(BASE!$G:$G,BASE!$B:$B,$B181,BASE!$L:$L,$G181,BASE!$J:$J,$C181,BASE!$A:$A,M$2) -> 0 | N181: =SUMIFS(BASE!$G:$G,BASE!$B:$B,$B181,BASE!$L:$L,$G181,BASE!$J:$J,$C181,BASE!$A:$A,N$2) -> 0 | O181: =SUMIFS(BASE!$G:$G,BASE!$B:$B,$B181,BASE!$L:$L,$G181,BASE!$J:$J,$C181,BASE!$A:$A,O$2) -> 0 | P181: =SUMIFS(BASE!$G:$G,BASE!$B:$B,$B181,BASE!$L:$L,$G181,BASE!$J:$J,$C181,BASE!$A:$A,P$2) -> 0 | Q181: =SUMIFS(BASE!$G:$G,BASE!$B:$B,$B181,BASE!$L:$L,$G181,BASE!$J:$J,$C181,BASE!$A:$A,Q$2) -> 0 | R181: =SUMIFS(BASE!$G:$G,BASE!$B:$B,$B181,BASE!$L:$L,$G181,BASE!$J:$J,$C181,BASE!$A:$A,R$2) -> 0 | ... V181: =SUMIFS(BASE!$G:$G,BASE!$B:$B,$B181,BASE!$L:$L,$G181,BASE!$J:$J,$C181,BASE!$A:$A,V$2) -> 0 | X181: =IF(AND(R181=0),"ZERADO","COM TROCAS") -> ZERADO
B182: Z404 | C182: CELLULAR.COM | D182: MABY APARECIDA DUARTE | E182: MARCOS LOPES PEDROSA JUNIOR | F182: NOVA LIMA | G182: MG | H182: =IFERROR(IF(_xlfn.XLOOKUP(B182,REPASSE!D:D,REPASSE!D:D)="","Não","Sim"),"Não") -> Não | I182: =IF(_xlfn.XLOOKUP(B182,'BOOST LIBERADO'!B:B,'BOOST LIBERADO'!B:B,"Não")="Não","Não","Sim") -> Sim | J182: =IF(AND(H182="Não",I182="Sim"),"Sim","Não") -> Sim | K182: =SUMIFS(BASE!$G:$G,BASE!$B:$B,$B182,BASE!$L:$L,$G182,BASE!$J:$J,$C182,BASE!$A:$A,K$2) -> 0 | L182: =SUMIFS(BASE!$G:$G,BASE!$B:$B,$B182,BASE!$L:$L,$G182,BASE!$J:$J,$C182,BASE!$A:$A,L$2) -> 0 | M182: =SUMIFS(BASE!$G:$G,BASE!$B:$B,$B182,BASE!$L:$L,$G182,BASE!$J:$J,$C182,BASE!$A:$A,M$2) -> 0 | N182: =SUMIFS(BASE!$G:$G,BASE!$B:$B,$B182,BASE!$L:$L,$G182,BASE!$J:$J,$C182,BASE!$A:$A,N$2) -> 0 | O182: =SUMIFS(BASE!$G:$G,BASE!$B:$B,$B182,BASE!$L:$L,$G182,BASE!$J:$J,$C182,BASE!$A:$A,O$2) -> 0 | P182: =SUMIFS(BASE!$G:$G,BASE!$B:$B,$B182,BASE!$L:$L,$G182,BASE!$J:$J,$C182,BASE!$A:$A,P$2) -> 0 | Q182: =SUMIFS(BASE!$G:$G,BASE!$B:$B,$B182,BASE!$L:$L,$G182,BASE!$J:$J,$C182,BASE!$A:$A,Q$2) -> 0 | R182: =SUMIFS(BASE!$G:$G,BASE!$B:$B,$B182,BASE!$L:$L,$G182,BASE!$J:$J,$C182,BASE!$A:$A,R$2) -> 0 | ... V182: =SUMIFS(BASE!$G:$G,BASE!$B:$B,$B182,BASE!$L:$L,$G182,BASE!$J:$J,$C182,BASE!$A:$A,V$2) -> 0 | X182: =IF(AND(R182=0),"ZERADO","COM TROCAS") -> ZERADO
B183: MXJG | C183: CELLULAR.COM | D183: MATEUS MARQUES VIANA | E183: MARCOS LOPES PEDROSA JUNIOR | F183: ITAUNA | G183: MG | H183: =IFERROR(IF(_xlfn.XLOOKUP(B183,REPASSE!D:D,REPASSE!D:D)="","Não","Sim"),"Não") -> Não | I183: =IF(_xlfn.XLOOKUP(B183,'BOOST LIBERADO'!B:B,'BOOST LIBERADO'!B:B,"Não")="Não","Não","Sim") -> Sim | J183: =IF(AND(H183="Não",I183="Sim"),"Sim","Não") -> Sim | K183: =SUMIFS(BASE!$G:$G,BASE!$B:$B,$B183,BASE!$L:$L,$G183,BASE!$J:$J,$C183,BASE!$A:$A,K$2) -> 0 | L183: =SUMIFS(BASE!$G:$G,BASE!$B:$B,$B183,BASE!$L:$L,$G183,BASE!$J:$J,$C183,BASE!$A:$A,L$2) -> 0 | M183: =SUMIFS(BASE!$G:$G,BASE!$B:$B,$B183,BASE!$L:$L,$G183,BASE!$J:$J,$C183,BASE!$A:$A,M$2) -> 0 | N183: =SUMIFS(BASE!$G:$G,BASE!$B:$B,$B183,BASE!$L:$L,$G183,BASE!$J:$J,$C183,BASE!$A:$A,N$2) -> 0 | O183: =SUMIFS(BASE!$G:$G,BASE!$B:$B,$B183,BASE!$L:$L,$G183,BASE!$J:$J,$C183,BASE!$A:$A,O$2) -> 0 | P183: =SUMIFS(BASE!$G:$G,BASE!$B:$B,$B183,BASE!$L:$L,$G183,BASE!$J:$J,$C183,BASE!$A:$A,P$2) -> 0 | Q183: =SUMIFS(BASE!$G:$G,BASE!$B:$B,$B183,BASE!$L:$L,$G183,BASE!$J:$J,$C183,BASE!$A:$A,Q$2) -> 0 | R183: =SUMIFS(BASE!$G:$G,BASE!$B:$B,$B183,BASE!$L:$L,$G183,BASE!$J:$J,$C183,BASE!$A:$A,R$2) -> 0 | ... V183: =SUMIFS(BASE!$G:$G,BASE!$B:$B,$B183,BASE!$L:$L,$G183,BASE!$J:$J,$C183,BASE!$A:$A,V$2) -> 0 | X183: =IF(AND(R183=0),"ZERADO","COM TROCAS") -> ZERADO
B184: 9PNA | C184: MAXMILIANO RODRIGUES | D184: JESSICA PEREIRA BOTELHO ARRUDA | E184: BRENNER SOUZA RODRIGUES | F184: TEOFILO OTONI | G184: MG | H184: =IFERROR(IF(_xlfn.XLOOKUP(B184,REPASSE!D:D,REPASSE!D:D)="","Não","Sim"),"Não") -> Não | I184: =IF(_xlfn.XLOOKUP(B184,'BOOST LIBERADO'!B:B,'BOOST LIBERADO'!B:B,"Não")="Não","Não","Sim") -> Sim | J184: =IF(AND(H184="Não",I184="Sim"),"Sim","Não") -> Sim | K184: =SUMIFS(BASE!$G:$G,BASE!$B:$B,$B184,BASE!$L:$L,$G184,BASE!$J:$J,$C184,BASE!$A:$A,K$2) -> 0 | L184: =SUMIFS(BASE!$G:$G,BASE!$B:$B,$B184,BASE!$L:$L,$G184,BASE!$J:$J,$C184,BASE!$A:$A,L$2) -> 0 | M184: =SUMIFS(BASE!$G:$G,BASE!$B:$B,$B184,BASE!$L:$L,$G184,BASE!$J:$J,$C184,BASE!$A:$A,M$2) -> 0 | N184: =SUMIFS(BASE!$G:$G,BASE!$B:$B,$B184,BASE!$L:$L,$G184,BASE!$J:$J,$C184,BASE!$A:$A,N$2) -> 0 | O184: =SUMIFS(BASE!$G:$G,BASE!$B:$B,$B184,BASE!$L:$L,$G184,BASE!$J:$J,$C184,BASE!$A:$A,O$2) -> 0 | P184: =SUMIFS(BASE!$G:$G,BASE!$B:$B,$B184,BASE!$L:$L,$G184,BASE!$J:$J,$C184,BASE!$A:$A,P$2) -> 0 | Q184: =SUMIFS(BASE!$G:$G,BASE!$B:$B,$B184,BASE!$L:$L,$G184,BASE!$J:$J,$C184,BASE!$A:$A,Q$2) -> 0 | R184: =SUMIFS(BASE!$G:$G,BASE!$B:$B,$B184,BASE!$L:$L,$G184,BASE!$J:$J,$C184,BASE!$A:$A,R$2) -> 0 | ... V184: =SUMIFS(BASE!$G:$G,BASE!$B:$B,$B184,BASE!$L:$L,$G184,BASE!$J:$J,$C184,BASE!$A:$A,V$2) -> 0 | X184: =IF(AND(R184=0),"ZERADO","COM TROCAS") -> ZERADO
B185: 63SQ | C185: MAX CEL GV LTDA | D185: JESSICA PEREIRA BOTELHO ARRUDA | E185: BRENNER SOUZA RODRIGUES | F185: GOVERNADOR VALADARES | G185: MG | H185: =IFERROR(IF(_xlfn.XLOOKUP(B185,REPASSE!D:D,REPASSE!D:D)="","Não","Sim"),"Não") -> Não | I185: =IF(_xlfn.XLOOKUP(B185,'BOOST LIBERADO'!B:B,'BOOST LIBERADO'!B:B,"Não")="Não","Não","Sim") -> Sim | J185: =IF(AND(H185="Não",I185="Sim"),"Sim","Não") -> Sim | K185: =SUMIFS(BASE!$G:$G,BASE!$B:$B,$B185,BASE!$L:$L,$G185,BASE!$J:$J,$C185,BASE!$A:$A,K$2) -> 0 | L185: =SUMIFS(BASE!$G:$G,BASE!$B:$B,$B185,BASE!$L:$L,$G185,BASE!$J:$J,$C185,BASE!$A:$A,L$2) -> 0 | M185: =SUMIFS(BASE!$G:$G,BASE!$B:$B,$B185,BASE!$L:$L,$G185,BASE!$J:$J,$C185,BASE!$A:$A,M$2) -> 0 | N185: =SUMIFS(BASE!$G:$G,BASE!$B:$B,$B185,BASE!$L:$L,$G185,BASE!$J:$J,$C185,BASE!$A:$A,N$2) -> 0 | O185: =SUMIFS(BASE!$G:$G,BASE!$B:$B,$B185,BASE!$L:$L,$G185,BASE!$J:$J,$C185,BASE!$A:$A,O$2) -> 0 | P185: =SUMIFS(BASE!$G:$G,BASE!$B:$B,$B185,BASE!$L:$L,$G185,BASE!$J:$J,$C185,BASE!$A:$A,P$2) -> 0 | Q185: =SUMIFS(BASE!$G:$G,BASE!$B:$B,$B185,BASE!$L:$L,$G185,BASE!$J:$J,$C185,BASE!$A:$A,Q$2) -> 0 | R185: =SUMIFS(BASE!$G:$G,BASE!$B:$B,$B185,BASE!$L:$L,$G185,BASE!$J:$J,$C185,BASE!$A:$A,R$2) -> 0 | ... V185: =SUMIFS(BASE!$G:$G,BASE!$B:$B,$B185,BASE!$L:$L,$G185,BASE!$J:$J,$C185,BASE!$A:$A,V$2) -> 0 | X185: =IF(AND(R185=0),"ZERADO","COM TROCAS") -> ZERADO
B186: M8XO | C186: TELECELL TELEFONIA LTDA - ME | D186: JOSIANA EMILIA SILVA FARIA | E186: KAROLINE LAMAS DE ANDRADE | F186: CATAGUASES | G186: MG | H186: =IFERROR(IF(_xlfn.XLOOKUP(B186,REPASSE!D:D,REPASSE!D:D)="","Não","Sim"),"Não") -> Não | I186: =IF(_xlfn.XLOOKUP(B186,'BOOST LIBERADO'!B:B,'BOOST LIBERADO'!B:B,"Não")="Não","Não","Sim") -> Sim | J186: =IF(AND(H186="Não",I186="Sim"),"Sim","Não") -> Sim | K186: =SUMIFS(BASE!$G:$G,BASE!$B:$B,$B186,BASE!$L:$L,$G186,BASE!$J:$J,$C186,BASE!$A:$A,K$2) -> 9 | L186: =SUMIFS(BASE!$G:$G,BASE!$B:$B,$B186,BASE!$L:$L,$G186,BASE!$J:$J,$C186,BASE!$A:$A,L$2) -> 7 | M186: =SUMIFS(BASE!$G:$G,BASE!$B:$B,$B186,BASE!$L:$L,$G186,BASE!$J:$J,$C186,BASE!$A:$A,M$2) -> 19 | N186: =SUMIFS(BASE!$G:$G,BASE!$B:$B,$B186,BASE!$L:$L,$G186,BASE!$J:$J,$C186,BASE!$A:$A,N$2) -> 16 | O186: =SUMIFS(BASE!$G:$G,BASE!$B:$B,$B186,BASE!$L:$L,$G186,BASE!$J:$J,$C186,BASE!$A:$A,O$2) -> 10 | P186: =SUMIFS(BASE!$G:$G,BASE!$B:$B,$B186,BASE!$L:$L,$G186,BASE!$J:$J,$C186,BASE!$A:$A,P$2) -> 13 | Q186: =SUMIFS(BASE!$G:$G,BASE!$B:$B,$B186,BASE!$L:$L,$G186,BASE!$J:$J,$C186,BASE!$A:$A,Q$2) -> 13 | R186: =SUMIFS(BASE!$G:$G,BASE!$B:$B,$B186,BASE!$L:$L,$G186,BASE!$J:$J,$C186,BASE!$A:$A,R$2) -> 4 | ... V186: =SUMIFS(BASE!$G:$G,BASE!$B:$B,$B186,BASE!$L:$L,$G186,BASE!$J:$J,$C186,BASE!$A:$A,V$2) -> 0 | X186: =IF(AND(R186=0),"ZERADO","COM TROCAS") -> COM TROCAS
B187: 9VBP | C187: FAJULUTI | D187: LUIS CARLOS DE ASSIS | E187: JORGE PEREIRA AZAMBUJA FILHO | F187: LAVRAS | G187: MG | H187: =IFERROR(IF(_xlfn.XLOOKUP(B187,REPASSE!D:D,REPASSE!D:D)="","Não","Sim"),"Não") -> Não | I187: =IF(_xlfn.XLOOKUP(B187,'BOOST LIBERADO'!B:B,'BOOST LIBERADO'!B:B,"Não")="Não","Não","Sim") -> Sim | J187: =IF(AND(H187="Não",I187="Sim"),"Sim","Não") -> Sim | K187: =SUMIFS(BASE!$G:$G,BASE!$B:$B,$B187,BASE!$L:$L,$G187,BASE!$J:$J,$C187,BASE!$A:$A,K$2) -> 0 | L187: =SUMIFS(BASE!$G:$G,BASE!$B:$B,$B187,BASE!$L:$L,$G187,BASE!$J:$J,$C187,BASE!$A:$A,L$2) -> 0 | M187: =SUMIFS(BASE!$G:$G,BASE!$B:$B,$B187,BASE!$L:$L,$G187,BASE!$J:$J,$C187,BASE!$A:$A,M$2) -> 0 | N187: =SUMIFS(BASE!$G:$G,BASE!$B:$B,$B187,BASE!$L:$L,$G187,BASE!$J:$J,$C187,BASE!$A:$A,N$2) -> 0 | O187: =SUMIFS(BASE!$G:$G,BASE!$B:$B,$B187,BASE!$L:$L,$G187,BASE!$J:$J,$C187,BASE!$A:$A,O$2) -> 1 | P187: =SUMIFS(BASE!$G:$G,BASE!$B:$B,$B187,BASE!$L:$L,$G187,BASE!$J:$J,$C187,BASE!$A:$A,P$2) -> 1 | Q187: =SUMIFS(BASE!$G:$G,BASE!$B:$B,$B187,BASE!$L:$L,$G187,BASE!$J:$J,$C187,BASE!$A:$A,Q$2) -> 4 | R187: =SUMIFS(BASE!$G:$G,BASE!$B:$B,$B187,BASE!$L:$L,$G187,BASE!$J:$J,$C187,BASE!$A:$A,R$2) -> 4 | ... V187: =SUMIFS(BASE!$G:$G,BASE!$B:$B,$B187,BASE!$L:$L,$G187,BASE!$J:$J,$C187,BASE!$A:$A,V$2) -> 0 | X187: =IF(AND(R187=0),"ZERADO","COM TROCAS") -> COM TROCAS
B188: OBT4 | C188: P.G.L CELULARES LTDA | D188: LUANA PAULA PICANCO CASTRO INOUE | E188: BRENNER SOUZA RODRIGUES | F188: MARIANA | G188: MG | H188: =IFERROR(IF(_xlfn.XLOOKUP(B188,REPASSE!D:D,REPASSE!D:D)="","Não","Sim"),"Não") -> Não | I188: =IF(_xlfn.XLOOKUP(B188,'BOOST LIBERADO'!B:B,'BOOST LIBERADO'!B:B,"Não")="Não","Não","Sim") -> Sim | J188: =IF(AND(H188="Não",I188="Sim"),"Sim","Não") -> Sim | K188: =SUMIFS(BASE!$G:$G,BASE!$B:$B,$B188,BASE!$L:$L,$G188,BASE!$J:$J,$C188,BASE!$A:$A,K$2) -> 0 | L188: =SUMIFS(BASE!$G:$G,BASE!$B:$B,$B188,BASE!$L:$L,$G188,BASE!$J:$J,$C188,BASE!$A:$A,L$2) -> 0 | M188: =SUMIFS(BASE!$G:$G,BASE!$B:$B,$B188,BASE!$L:$L,$G188,BASE!$J:$J,$C188,BASE!$A:$A,M$2) -> 0 | N188: =SUMIFS(BASE!$G:$G,BASE!$B:$B,$B188,BASE!$L:$L,$G188,BASE!$J:$J,$C188,BASE!$A:$A,N$2) -> 0 | O188: =SUMIFS(BASE!$G:$G,BASE!$B:$B,$B188,BASE!$L:$L,$G188,BASE!$J:$J,$C188,BASE!$A:$A,O$2) -> 0 | P188: =SUMIFS(BASE!$G:$G,BASE!$B:$B,$B188,BASE!$L:$L,$G188,BASE!$J:$J,$C188,BASE!$A:$A,P$2) -> 0 | Q188: =SUMIFS(BASE!$G:$G,BASE!$B:$B,$B188,BASE!$L:$L,$G188,BASE!$J:$J,$C188,BASE!$A:$A,Q$2) -> 0 | R188: =SUMIFS(BASE!$G:$G,BASE!$B:$B,$B188,BASE!$L:$L,$G188,BASE!$J:$J,$C188,BASE!$A:$A,R$2) -> 1 | ... V188: =SUMIFS(BASE!$G:$G,BASE!$B:$B,$B188,BASE!$L:$L,$G188,BASE!$J:$J,$C188,BASE!$A:$A,V$2) -> 0 | X188: =IF(AND(R188=0),"ZERADO","COM TROCAS") -> COM TROCAS
